Workbook
Name StartingBalance: #REF!

Sheet Resumen
B1: =IFERROR(__xludf.DUMMYFUNCTION("GOOGLEFINANCE((""CURRENCY:CLF/CLP""))"),40825.75) -> 40825.75 | F1: Dolar | G1: =IFERROR(__xludf.DUMMYFUNCTION("GOOGLEFINANCE((""CURRENCY:USDCLP""))"),925.24) -> 925.24
B2: Gastos | H2: Pagos
B3: PPTO | C3: =D9 -> 1955021.9 | D3: =IFERROR(__xludf.DUMMYFUNCTION("SPARKLINE(C3,{""charttype"",""bar"";""max"",max(C3:C4);""color1"",""#AEB7C0""})"),"") | H3: Previsto | I3: =J9 -> 1955021.9 | J3: =IFERROR(__xludf.DUMMYFUNCTION("SPARKLINE(I3,{""charttype"",""bar"";""max"",max(I3:I4);""color1"",""#AEB7C0""})"),"")
B4: Gastado | C4: =E9 -> 1042755.6 | D4: =IFERROR(__xludf.DUMMYFUNCTION("SPARKLINE(C4,{""charttype"",""bar"";""max"",max(C3:C4);""color1"",""#334960""})"),"") | H4: Amex | I4: =IFERROR(__xludf.DUMMYFUNCTION("IMPORTRANGE(""https://docs.google.com/spreadsheets/d/1eg8N2weYKMcWwj9jcJqBX-y0loZRILY9c1SDJETZtoI/edit?pli=1&gid=124507033#gid=124507033&range=O40"",""O40"")"),176719.02083333395) -> 176719.02
B5: Pagado | C5: =K9 -> 0 | D5: =IFERROR(__xludf.DUMMYFUNCTION("SPARKLINE(C5,{""charttype"",""bar"";""max"",max(I3,C5);""color1"",""#334960""})"),"") | H5: Paga Jose | I5: =IFERROR(__xludf.DUMMYFUNCTION("IMPORTRANGE(""https://docs.google.com/spreadsheets/d/1eg8N2weYKMcWwj9jcJqBX-y0loZRILY9c1SDJETZtoI/edit?pli=1&gid=124507033#gid=124507033&range=M42"",""M42"")"),47714.13562500017) -> 47714.136
B7: Gastos | H7: Ingresos
D8: Previsto | E8: Pagado | F8: Difer. | J8: Previsto | K8: Real | L8: Difer. | O8: Por pagar pp
A9: Pagado | B9: Totales | D9: =sum(D10:D26) -> 1955021.9 | E9: =sum(E10:E26) -> 1042755.6 | F9: =sum(F10:F26) -> 912266.37 | H9: Totales | J9: =sum(J10:J26) -> 1955021.9 | K9: =sum(K10:K26) -> 0 | L9: =sum(L10:L26) -> -1955021.9 | N9: Jav | O9: =Transacciones!N3 -> 176000
B10: Spotify | D10: =Analisis!B2 -> 7400 | E10: =if(isblank($B10), "", sumif(Transacciones!$E:$E,$B10,Transacciones!$C:$C)) -> 7094 | F10: =if(isblank($B10), "", D10-E10) -> 306 | H10: Javier | J10: =C3*1 -> 1955021.9 | K10: =O10 | L10: =if(isblank($H10:$H11), "", K10:K11-J10:J11) -> -1955021.9 | N10: Por pagar
B11: Netflix | D11: 14253 | E11: =if(isblank($B11), "", sumif(Transacciones!$E:$E,$B11,Transacciones!$C:$C)) -> 14253 | F11: =if(isblank($B11), "", D11-E11) -> 0
B12: Supermercado | D12: 322000 | E12: =if(isblank($B12), "", sumif(Transacciones!$E:$E,$B12,Transacciones!$C:$C)) -> 176000 | F12: =if(isblank($B12), "", D12-E12) -> 146000
B13: Arriendo | D13: =E13 -> 704652.44 | E13: =if(isblank($B13), "", sumif(Transacciones!$E:$E,$B13,Transacciones!$C:$C)) -> 704652.44 | F13: =if(isblank($B13), "", D13-E13) -> 0
B14: Gastos comunes | D14: =Analisis!B6 -> 270000 | E14: =if(isblank($B14), "", sumif(Transacciones!$E:$E,$B14,Transacciones!$C:$C)) -> 0 | F14: =if(isblank($B14), "", D14-E14) -> 270000
B15: Nana | D15: =37000*3 -> 111000 | E15: =if(isblank($B15), "", sumif(Transacciones!$E:$E,$B15,Transacciones!$C:$C)) -> 74000 | F15: =if(isblank($B15), "", D15-E15) -> 37000
B16: Entel | D16: =Analisis!B8 -> 29850 | E16: =if(isblank($B16), "", sumif(Transacciones!$E:$E,$B16,Transacciones!$C:$C)) -> 18990 | F16: =if(isblank($B16), "", D16-E16) -> 10860 | K16: =if(isblank($H16), "", sumif(Transacciones!$K:$K,$H16,Transacciones!$I:$I)) | L16: =if(isblank($H16), "", K16-J16)
B17: Luz | D17: =Analisis!B9 -> 82107 | E17: =if(isblank($B17), "", sumif(Transacciones!$E:$E,$B17,Transacciones!$C:$C)) -> 0 | F17: =if(isblank($B17), "", D17-E17) -> 82107 | L17: =if(isblank($H17), "", K17-J17)
B18: Agua | D18: =Analisis!B10 -> 15860 | E18: =if(isblank($B18), "", sumif(Transacciones!$E:$E,$B18,Transacciones!$C:$C)) -> 0 | F18: =if(isblank($B18), "", D18-E18) -> 15860 | K18: =if(isblank($H18), "", sumif(Transacciones!$K:$K,$H18,Transacciones!$I:$I)) | L18: =if(isblank($H18), "", K18-J18)
B19: Gas | D19: =Analisis!B11 -> 8600 | E19: =if(isblank($B19), "", sumif(Transacciones!$E:$E,$B19,Transacciones!$C:$C)) -> 0 | F19: =if(isblank($B19), "", D19-E19) -> 8600 | L19: =if(isblank($H19), "", K19-J19)
B20: Reparaciones y hogar | D20: =Analisis!B12 -> 0 | E20: =if(isblank($B20), "", sumif(Transacciones!$E:$E,$B20,Transacciones!$C:$C)) -> 0 | F20: =if(isblank($B20), "", D20-E20) -> 0 | K20: =if(isblank($H20), "", sumif(Transacciones!$K:$K,$H20,Transacciones!$I:$I)) | L20: =if(isblank($H20), "", K20-J20)
B21: Seguro depto | D21: =48917/40509*B1 -> 49299.494 | E21: =if(isblank($B21), "", sumif(Transacciones!$E:$E,$B21,Transacciones!$C:$C)) -> 47766.128 | F21: =if(isblank($B21), "", D21-E21) -> 1533.3668 | K21: =if(isblank($H21), "", sumif(Transacciones!$K:$K,$H21,Transacciones!$I:$I)) | L21: =if(isblank($H21), "", K21-J21)
B22: tag | D22: 140000 | E22: =if(isblank($B22), "", sumif(Transacciones!$E:$E,$B22,Transacciones!$C:$C)) -> 0 | F22: =if(isblank($B22), "", D22-E22) -> 140000 | K22: =if(isblank($H22), "", sumif(Transacciones!$K:$K,$H22,Transacciones!$I:$I)) | L22: =if(isblank($H22), "", K22-J22)
B23: bencina/luz | D23: 200000 | E23: =if(isblank($B23), "", sumif(Transacciones!$E:$E,$B23,Transacciones!$C:$C)) -> 0 | F23: =if(isblank($B23), "", D23-E23) -> 200000 | K23: =if(isblank($H23), "", sumif(Transacciones!$K:$K,$H23,Transacciones!$I:$I)) | L23: =if(isblank($H23), "", K23-J23)
D25: =D6:F6
E26: =if(isblank($B26), "", sumif(Transacciones!$E:$E,$B26,Transacciones!$C:$C)) | F26: =if(isblank($B26), "", D26-E26) | K26: =if(isblank($H26), "", sumif(Transacciones!$K:$K,$H26,Transacciones!$I:$I)) | L26: =if(isblank($H26), "", K26-J26)

Sheet JOSE
A1: =-(B1-C1) -> 0 | B1: =SUM(B3:B1001)*0.73 -> 0 | C1: =SUM(C3:C1001)*0.27 -> 0 | E1: Dolar | F1: =Resumen!G1+2 -> 927.24
A2: ITEM | B2: Jose | C2: Javier | F2: 45467
E3: =1480000/(3900000+1480000) -> 0.27509294 | F3: café | H3: =25000+28300 -> 53300 | J3: Tag vuelta | K3: 2318
F4: cafetería | H4: 12390 | J4: Tag ida | K4: 4209
F5: pia | H5: -27000 | J5: Bencina | K5: =19*2/14*1350 -> 3664.2857
F6: entradas | G6: 80500
F7: Bencina | H7: 13250
F8: johny rockets | H8: =35600-13500 -> 22100
F9: lavado | H9: 6500
F10: Bencina | G10: 52061
F11: Tag | G11: 44275
F12: Seguro | G12: 55079
F13: Tag | G13: 6075
F14: Burger king | H14: 5800
F15: Padel | H15: 17000
F16: Bencina | H16: 10000
F17: Awto | H17: 5400
F18: Goodmeal | H18: 13000
F19: Completos | H19: =-7700*4 -> -30800
F20: Cintas | H20: 8000
F21: Almuerzo | H21: 19500
F22: Tag | G22: 64959
F23: 45497
F24: cabritas | H24: 8400
F25: padel | H25: 15000
F26: desayuno | H26: 20000
F27: padel seba | H27: 9000
F28: Seguro Argo | G28: 55258
F29: padel 8 | H29: 15000
F30: seguro
F31: tag | G31: 11837
F32: fork | H32: 12990
F33: wallys | H33: 18000
F34: padel 16 | H34: 10000
F35: Tag | G35: 41660
F36: andi | H36: 20000
F37: veggies | H37: 4500
F44: 45528
F45: Juguetes Lola | G45: 15400
F46: Seguro Argo | G46: 55000
...

Sheet Analisis
B1: Maximo | C1: Minimo | D1: Promedio | E1: 44061 | F1: 44092 | G1: 44122 | H1: 44153 | I1: 44183 | J1: 43849 | K1: 43515 | L1: 43909 | M1: 44305 | N1: 44700 | O1: 45096 | P1: 45492 | Q1: 45888 | R1: 46284 | S1: 46679 | T1: 47076 | U1: 47471 | V1: 43850 | W1: 43881 | X1: 43910 | Y1: 43941 | Z1: 43971 | AA1: 44002 | AB1: 44032 | AC1: 44063 | AD1: 44094 | AE1: 44124 | AF1: 44155 | AG1: 44185 | AH1: 44217 | AI1: 44248 | AJ1: Marzo 21 | AK1: Abril 21 | AL1: Mayo 21 | AM1: Junio 21 | AN1: Julio 21 | AO1: 44429 | AP1: 44460 | AQ1: 44490 | AR1: noviembre 21 | AS1: diciembre 21 | AT1: enero 22 | AU1: febrero 22 | AV1: marzo 22 | AW1: abril 22 | AX1: mayo 22 | AY1: junio 22 | AZ1: julio 22 | BA1: agosto 22 | BB1: septiembre 22 | BC1: octubre 22 | BD1: noviembre 22 | BE1: diciembre 22 | BF1: enero 23 | BG1: febrero 23 | BH1: marzo 23 | BI1: abril 23 | BJ1: mayo 23 | BK1: junio 23 | BL1: julio 23 | BM1: agosto 23 | BN1: septiembre 23 | BO1: octubre 23 | BP1: noviembre 23 | BQ1: diciembre 23 | BR1: enero 24 | BS1: febrero 24 | BT1: marzo 24 | BU1: abril 24 | BV1: mayo 24 | BW1: junio 24 | BX1: julio 24 | BY1: agosto 24 | BZ1: septiembre 24 | CA1: octubre 24 | CB1: noviembre 24 | CC1: diciembre 24 | CD1: enero 25 | CE1: febrero 25 | CF1: marzo 25 | CG1: abril 25 | CH1: mayo 25 | CI1: junio 25 | CJ1: julio 25 | CK1: agosto 25 | CL1: sep 25 | CM1: oct 25 | CN1: nov 25 | CO1: dic 25 | CP1: ene 26
A2: Spotify | B2: =MAX(BN2:ZZ2) -> 7400 | C2: =MIN(AK2:ZZ2) -> 6300 | D2: =AVERAGE(AK2:ZZ2) -> 6746.1786 | E2: =SUMIF(Agosto!$E$5:$E$25,$A2,Agosto!$C$5:$C$25) -> 5361 | F2: =SUMIF(Septiembre!$E$5:$E$25,$A2,Septiembre!$C$5:$C$25) -> 5361 | G2: =SUMIF(octubre!$E$5:E$25,$A2,octubre!$C$5:$C$25) -> 5361 | H2: =SUMIF(noviembre!$E$5:F$25,$A2,noviembre!$C$5:$C$25) -> 5361 | I2: =SUMIF(Diciembre!$E$5:CQ$25,$A2,Diciembre!$C$5:$C$25) -> 5361 | J2: =SUMIF(Enero!$E$5:E$25,$A2,Enero!$C$5:$C$25) -> 5361 | K2: =SUMIF(febrero!$E$5:$E$25,$A2,febrero!$C$5:CQ$25) -> 5361 | L2: =SUMIF(Marzo!$E$5:$E$25,$A2,Marzo!$C$5:CQ$25) -> 5361 | M2: =SUMIF(Abril!$E$5:$E$25,$A2,Abril!$C$5:CQ$25) -> 5361 | N2: =SUMIF(Mayo!$E$5:$E$25,$A2,Mayo!$C$5:CQ$25) -> 5361 | O2: =SUMIF(Junio!$E$5:$E$25,$A2,Junio!$C$5:CQ$25) -> 5361 | P2: =SUMIF(Julio!$E$5:$E$25,$A2,Julio!$C$5:CQ$25) -> 5361 | Q2: =SUMIF('Agosto 19'!$E$5:$E$23,$A2,'Agosto 19'!$C$5:CQ$25) -> 5361 | R2: =SUMIF('Septiembre 19'!$E$5:$E$23,$A2,'Septiembre 19'!$C$5:CQ$25) -> 5361 | S2: =SUMIF('Octubre 19'!$E$5:$E$23,$A2,'Octubre 19'!$C$5:CQ$25) -> 5361 | T2: =SUMIF('Noviembre 19'!$E$5:$E$23,$A2,'Noviembre 19'!$C$5:CQ$25) -> 5361 | U2: =SUMIF('Diciembre 19'!$E$5:$E$23,$A2,'Diciembre 19'!$C$5:CQ$25) -> 5361 | V2: =SUMIF('Enero 20'!$E$5:$E$23,$A2,'Enero 20'!$C$5:CQ$25) -> 5361 | W2: =SUMIF('Febrero 20'!$E$5:$E$23,$A2,'Febrero 20'!$C$5:CQ$25) -> 5990 | X2: =SUMIF('Marzo 20'!$E$5:$E$23,$A2,'Marzo 20'!$C$5:CQ$25) -> 5990 | Y2: =SUMIF('Abril 20'!$E$5:$E$23,$A2,'Abril 20'!$C$5:CQ$25) -> 5990 | Z2: =SUMIF('Mayo 20'!$E$5:$E$23,$A2,'Mayo 20'!$C$5:CQ$25) -> 5990 | AA2: =SUMIF('Junio 20'!$E$5:$E$23,$A2,'Junio 20'!$C$5:CQ$25) -> 5990 | AB2: =SUMIF('Julio 20'!$E$5:$E$23,$A2,'Julio 20'!$C$5:CQ$25) -> 5990 | AC2: =SUMIF('Agosto 20'!$E$5:$E$23,$A2,'Agosto 20'!$C$5:CQ$25) -> 5990 | AD2: =SUMIF('Septiembre 20'!$E$5:$E$23,$A2,'Septiembre 20'!$C$5:CQ$25) -> 5990 | AE2: =SUMIF('octubre 20'!$E$5:$E$23,$A2,'octubre 20'!$C$5:CQ$25) -> 5990 | AF2: =SUMIF('noviembre 20'!$E$5:$E$23,$A2,'noviembre 20'!$C$5:CQ$25) -> 5990 | AG2: =SUMIF('diciembre 20'!$E$5:$E$23,$A2,'diciembre 20'!$C$5:CQ$25) -> 5990 | AH2: =SUMIF('enero 21'!$E$5:$E$23,$A2,'enero 21'!$C$5:CQ$25) -> 6300 | AI2: =SUMIF('febrero 21'!$E$5:$E$23,$A2,'febrero 21'!$C$5:CQ$25) -> 6300 | AJ2: =SUMIF('marzo 21'!$E$5:$E$23,$A2,'marzo 21'!$C$5:CQ$25) -> 6300 | AK2: =SUMIF('abril 21'!$E$5:$E$23,$A2,'abril 21'!$C$5:CQ$25) -> 6300 | AL2: =SUMIF('mayo 21'!$E$5:$E$23,$A2,'mayo 21'!$C$5:CQ$25) -> 6300 | AM2: =SUMIF('Junio 21'!$E$5:$E$23,$A2,'Junio 21'!$C$5:CQ$25) -> 6300 | AN2: =SUMIF('Julio 21'!$E$5:$E$23,$A2,'Julio 21'!$C$5:CQ$25) -> 6300 | AO2: =SUMIF('Agosto 21'!$E$5:$E$23,$A2,'Agosto 21'!$C$5:CQ$25) -> 6300 | AP2: =SUMIF('Septiembre 21'!$E$5:$E$23,$A2,'Septiembre 21'!$C$5:CQ$25) -> 6300 | AQ2: =SUMIF('Octubre 21'!$E$5:$E$23,$A2,'Octubre 21'!$C$5:CQ$25) -> 6300 | AR2: =SUMIF('Noviembre 21'!$E$5:$E$23,$A2,'Noviembre 21'!$C$5:CQ$25) -> 6300 | AS2: =SUMIF('Diciembre 21'!$E$5:$E$23,$A2,'Noviembre 21'!$C$5:CQ$25) -> 6300 | AT2: =SUMIF('Enero 22'!$E$5:$E$23,$A2,'Enero 22'!$C$5:CQ$25) -> 6300 | AU2: =SUMIF('Febrero 22'!$E$5:$E$23,$A2,'Febrero 22'!$C$5:CQ$25) -> 6300 | AV2: =SUMIF('Marzo 22'!$E$5:$E$23,$A2,'Marzo 22'!$C$5:CQ$25) -> 6300 | AW2: =SUMIF('Abril 22'!$E$5:$E$23,$A2,'Abril 22'!$C$5:CQ$25) -> 6300 | AX2: =SUMIF('Mayo 22'!$E$5:$E$23,$A2,'Mayo 22'!$C$5:CQ$25) -> 6300 | AY2: =SUMIF('Junio 22'!$E$5:$E$23,$A2,'Junio 22'!$C$5:CQ$25) -> 6300 | AZ2: =SUMIF('Julio 22'!$E$5:$E$23,$A2,'Julio 22'!$C$5:CQ$25) -> 6300 | BA2: =SUMIF('Agosto 22'!$E$5:$E$23,$A2,'Agosto 22'!$C$5:CQ$25) -> 6300 | BB2: =SUMIF('septiembre 22'!$E$5:$E$23,$A2,'septiembre 22'!$C$5:CQ$25) -> 6300 | BC2: =SUMIF('octubre 22'!$E$5:$E$23,$A2,'octubre 22'!$C$5:CQ$25) -> 6300 | BD2: =SUMIF('noviembre 22'!$E$5:$E$23,$A2,'noviembre 22'!$C$5:CQ$25) -> 6300 | BE2: =SUMIF('diciembre 22'!$E$5:$E$23,$A2,'noviembre 22'!$C$5:CQ$25) -> 6300 | BF2: =SUMIF('Enero 23'!$E$5:$E$23,$A2,'Enero 23'!$C$5:CQ$25) -> 6300 | BG2: =SUMIF('Febrero 23'!$E$5:$E$23,$A2,'Febrero 23'!$C$5:CQ$25) -> 6300 | BH2: =SUMIF('Marzo 23'!$E$5:$E$23,$A2,'Marzo 23'!$C$5:CQ$25) -> 6300 | BI2: =SUMIF('Abril 23'!$E$5:$E$23,$A2,'Abril 23'!$C$5:CQ$25) -> 6300 | BJ2: =SUMIF('Mayo 23'!$E$5:$E$23,$A2,'Mayo 23'!$C$5:CQ$25) -> 6300 | BK2: =SUMIF('Junio 23'!$E$5:$E$23,$A2,'Junio 23'!$C$5:CQ$25) -> 6300 | BL2: =SUMIF('Julio 23'!$E$5:$E$23,$A2,'Julio 23'!$C$5:CQ$25) -> 6300 | BM2: =SUMIF('Agosto 23'!$E$5:$E$23,$A2,'Agosto 23'!$C$5:CQ$25) -> 7400 | BN2: =SUMIF('Septiembre 23'!$E$5:$E$23,$A2,'Septiembre 23'!$C$5:CQ$25) -> 7400 | BO2: =SUMIF('Octubre 23'!$E$5:$E$23,$A2,'Octubre 23'!$C$5:CQ$25) -> 7400 | BP2: =SUMIF('Noviembre 23'!$E$5:$E$23,$A2,'Noviembre 23'!$C$5:CQ$25) -> 7400 | BQ2: =SUMIF('Diciembre 23'!$E$5:$E$23,$A2,'Diciembre 23'!$C$5:CQ$25) -> 7400 | BR2: =SUMIF('Enero 24'!$E$5:$E$23,$A2,'Enero 24'!$C$5:CQ$25) -> 7400 | BS2: =SUMIF('Febrero 24'!$E$5:$E$23,$A2,'Febrero 24'!$C$5:CQ$25) -> 7400 | BT2: =SUMIF('Marzo 24'!$E$5:$E$23,$A2,'Marzo 24'!$C$5:CQ$25) -> 7400 | BU2: =SUMIF('abril 24'!$E$5:$E$23,$A2,'abril 24'!$C$5:CQ$25) -> 7400 | BV2: =SUMIF('Mayo 24'!$E$5:$E$23,$A2,'Mayo 24'!$C$5:CQ$25) -> 7094 | BW2: =SUMIF('Junio 24'!$E$5:$E$23,$A2,'Junio 24'!$C$5:CQ$25) -> 7094 | BX2: =SUMIF('Julio 24'!$E$5:$E$23,$A2,'Julio 24'!$C$5:CQ$25) -> 7094 | BY2: =SUMIF('Agosto 24'!$E$5:$E$23,$A2,'Agosto 24'!$C$5:CQ$25) -> 7094 | BZ2: =SUMIF('Septiembre 24'!$E$5:$E$23,$A2,'Septiembre 24'!$C$5:CQ$25) -> 7094 | CA2: =SUMIF('Octubre 24'!$E$5:$E$23,$A2,'Octubre 24'!$C$5:CQ$25) -> 7094 | CB2: =SUMIF('Noviembre 24'!$E$5:$E$23,$A2,'Noviembre 24'!$C$5:CQ$25) -> 7094 | CC2: =SUMIF('Diciembre 24'!$E$5:$E$23,$A2,'Diciembre 24'!$C$5:CQ$25) -> 7094 | CD2: =SUMIF('Enero 25'!$E$5:$E$23,$A2,'Enero 25'!$C$5:CQ$25) -> 7094 | CE2: =SUMIF('febrero 25'!$E$5:$E$23,$A2,'febrero 25'!$C$5:CQ$25) -> 7094 | CF2: =SUMIF('marzo 25'!$E$5:$E$23,$A2,'marzo 25'!$C$5:CQ$25) -> 7094 | CG2: =SUMIF('abril 25'!$E$5:$E$23,$A2,'abril 25'!$C$5:CQ$25) -> 7094 | CH2: =SUMIF('Mayo 25'!$E$5:$E$23,$A2,'Mayo 25'!$C$5:CQ$25) -> 7094 | CI2: =SUMIF('Junio 25'!$E$5:$E$23,$A2,'Junio 25'!$C$5:CQ$25) -> 7094 | CJ2: =SUMIF('Julio 25'!$E$5:$E$23,$A2,'Julio 25'!$C$5:CQ$25) -> 7094 | CK2: =SUMIF('Agosto 25'!$E$5:$E$23,$A2,'Agosto 25'!$C$5:CQ$25) -> 7094 | CL2: =SUMIF('Septiembre 25'!$E$5:$E$23,$A2,'Septiembre 25'!$C$5:CQ$25) -> 7094 | CM2: =SUMIF('Octubre 25'!$E$5:$E$23,$A2,'Octubre 25'!$C$5:CQ$25) -> 7094 | CN2: =SUMIF('noviembre 25'!$E$5:$E$23,$A2,'noviembre 25'!$C$5:CQ$25) -> 7094
A3: Netflix | B3: =MAX(BN3:ZZ3) -> 14253 | C3: =MIN(AK3:ZZ3) -> 10700 | D3: =AVERAGE(AK3:ZZ3) -> 11924.946 | E3: =SUMIF(Agosto!$E$5:$E$25,$A3,Agosto!$C$5:$C$25) -> 7390 | F3: =SUMIF(Septiembre!$E$5:$E$25,$A3,Septiembre!$C$5:$C$25) -> 7390 | G3: =SUMIF(octubre!$E$5:E$25,$A3,octubre!$C$5:$C$25) -> 7390 | H3: =SUMIF(noviembre!$E$5:F$25,$A3,noviembre!$C$5:$C$25) -> 7390 | I3: =SUMIF(Diciembre!$E$5:CQ$25,$A3,Diciembre!$C$5:$C$25) -> 7390 | J3: =SUMIF(Enero!$E$5:E$25,$A3,Enero!$C$5:$C$25) -> 7390 | K3: =SUMIF(febrero!$E$5:$E$25,$A3,febrero!$C$5:CQ$25) -> 7390 | L3: =SUMIF(Marzo!$E$5:$E$25,$A3,Marzo!$C$5:CQ$25) -> 7390 | M3: =SUMIF(Abril!$E$5:$E$25,$A3,Abril!$C$5:CQ$25) -> 7390 | N3: =SUMIF(Mayo!$E$5:$E$25,$A3,Mayo!$C$5:CQ$25) -> 7390 | O3: =SUMIF(Junio!$E$5:$E$25,$A3,Junio!$C$5:CQ$25) -> 7390 | P3: =SUMIF(Julio!$E$5:$E$25,$A3,Julio!$C$5:CQ$25) -> 7390 | Q3: =SUMIF('Agosto 19'!$E$5:$E$23,$A3,'Agosto 19'!$C$5:CQ$25) -> 7390 | R3: =SUMIF('Septiembre 19'!$E$5:$E$23,$A3,'Septiembre 19'!$C$5:CQ$25) -> 7390 | S3: =SUMIF('Octubre 19'!$E$5:$E$23,$A3,'Octubre 19'!$C$5:CQ$25) -> 7390 | T3: =SUMIF('Noviembre 19'!$E$5:$E$23,$A3,'Noviembre 19'!$C$5:CQ$25) -> 8983.6 | U3: =SUMIF('Diciembre 19'!$E$5:$E$23,$A3,'Diciembre 19'!$C$5:CQ$25) -> 8983.6 | V3: =SUMIF('Enero 20'!$E$5:$E$23,$A3,'Enero 20'!$C$5:CQ$25) -> 8983.6 | W3: =SUMIF('Febrero 20'!$E$5:$E$23,$A3,'Febrero 20'!$C$5:CQ$25) -> 8990 | X3: =SUMIF('Marzo 20'!$E$5:$E$23,$A3,'Marzo 20'!$C$5:CQ$25) -> 8990 | Y3: =SUMIF('Abril 20'!$E$5:$E$23,$A3,'Abril 20'!$C$5:CQ$25) -> 8990 | Z3: =SUMIF('Mayo 20'!$E$5:$E$23,$A3,'Mayo 20'!$C$5:CQ$25) -> 8990 | AA3: =SUMIF('Junio 20'!$E$5:$E$23,$A3,'Junio 20'!$C$5:CQ$25) -> 8990 | AB3: =SUMIF('Julio 20'!$E$5:$E$23,$A3,'Julio 20'!$C$5:CQ$25) -> 8990 | AC3: =SUMIF('Agosto 20'!$E$5:$E$23,$A3,'Agosto 20'!$C$5:CQ$25) -> 10700 | AD3: =SUMIF('Septiembre 20'!$E$5:$E$23,$A3,'Septiembre 20'!$C$5:CQ$25) -> 10700 | AE3: =SUMIF('octubre 20'!$E$5:$E$23,$A3,'octubre 20'!$C$5:CQ$25) -> 10700 | AF3: =SUMIF('noviembre 20'!$E$5:$E$23,$A3,'noviembre 20'!$C$5:CQ$25) -> 10700 | AG3: =SUMIF('diciembre 20'!$E$5:$E$23,$A3,'diciembre 20'!$C$5:CQ$25) -> 10700 | AH3: =SUMIF('enero 21'!$E$5:$E$23,$A3,'enero 21'!$C$5:CQ$25) -> 10700 | AI3: =SUMIF('febrero 21'!$E$5:$E$23,$A3,'febrero 21'!$C$5:CQ$25) -> 10700 | AJ3: =SUMIF('marzo 21'!$E$5:$E$23,$A3,'marzo 21'!$C$5:CQ$25) -> 10700 | AK3: =SUMIF('abril 21'!$E$5:$E$23,$A3,'abril 21'!$C$5:CQ$25) -> 10700 | AL3: =SUMIF('mayo 21'!$E$5:$E$23,$A3,'mayo 21'!$C$5:CQ$25) -> 10700 | AM3: =SUMIF('Junio 21'!$E$5:$E$23,$A3,'Junio 21'!$C$5:CQ$25) -> 10700 | AN3: =SUMIF('Julio 21'!$E$5:$E$23,$A3,'Julio 21'!$C$5:CQ$25) -> 10700 | AO3: =SUMIF('Agosto 21'!$E$5:$E$23,$A3,'Agosto 21'!$C$5:CQ$25) -> 10700 | AP3: =SUMIF('Septiembre 21'!$E$5:$E$23,$A3,'Septiembre 21'!$C$5:CQ$25) -> 10700 | AQ3: =SUMIF('Octubre 21'!$E$5:$E$23,$A3,'Octubre 21'!$C$5:CQ$25) -> 10700 | AR3: =SUMIF('Noviembre 21'!$E$5:$E$23,$A3,'Noviembre 21'!$C$5:CQ$25) -> 10700 | AS3: =SUMIF('Diciembre 21'!$E$5:$E$23,$A3,'Noviembre 21'!$C$5:CQ$25) -> 10700 | AT3: =SUMIF('Enero 22'!$E$5:$E$23,$A3,'Enero 22'!$C$5:CQ$25) -> 10700 | AU3: =SUMIF('Febrero 22'!$E$5:$E$23,$A3,'Febrero 22'!$C$5:CQ$25) -> 10700 | AV3: =SUMIF('Marzo 22'!$E$5:$E$23,$A3,'Marzo 22'!$C$5:CQ$25) -> 10700 | AW3: =SUMIF('Abril 22'!$E$5:$E$23,$A3,'Abril 22'!$C$5:CQ$25) -> 10700 | AX3: =SUMIF('Mayo 22'!$E$5:$E$23,$A3,'Mayo 22'!$C$5:CQ$25) -> 10700 | AY3: =SUMIF('Junio 22'!$E$5:$E$23,$A3,'Junio 22'!$C$5:CQ$25) -> 10700 | AZ3: =SUMIF('Julio 22'!$E$5:$E$23,$A3,'Julio 22'!$C$5:CQ$25) -> 10700 | BA3: =SUMIF('Agosto 22'!$E$5:$E$23,$A3,'Agosto 22'!$C$5:CQ$25) -> 10700 | BB3: =SUMIF('septiembre 22'!$E$5:$E$23,$A3,'septiembre 22'!$C$5:CQ$25) -> 10700 | BC3: =SUMIF('octubre 22'!$E$5:$E$23,$A3,'octubre 22'!$C$5:CQ$25) -> 10700 | BD3: =SUMIF('noviembre 22'!$E$5:$E$23,$A3,'noviembre 22'!$C$5:CQ$25) -> 10700 | BE3: =SUMIF('diciembre 22'!$E$5:$E$23,$A3,'noviembre 22'!$C$5:CQ$25) -> 10700 | BF3: =SUMIF('Enero 23'!$E$5:$E$23,$A3,'Enero 23'!$C$5:CQ$25) -> 10700 | BG3: =SUMIF('Febrero 23'!$E$5:$E$23,$A3,'Febrero 23'!$C$5:CQ$25) -> 10700 | BH3: =SUMIF('Marzo 23'!$E$5:$E$23,$A3,'Marzo 23'!$C$5:CQ$25) -> 10700 | BI3: =SUMIF('Abril 23'!$E$5:$E$23,$A3,'Abril 23'!$C$5:CQ$25) -> 10700 | BJ3: =SUMIF('Mayo 23'!$E$5:$E$23,$A3,'Mayo 23'!$C$5:CQ$25) -> 10700 | BK3: =SUMIF('Junio 23'!$E$5:$E$23,$A3,'Junio 23'!$C$5:CQ$25) -> 10700 | BL3: =SUMIF('Julio 23'!$E$5:$E$23,$A3,'Julio 23'!$C$5:CQ$25) -> 10700 | BM3: =SUMIF('Agosto 23'!$E$5:$E$23,$A3,'Agosto 23'!$C$5:CQ$25) -> 10700 | BN3: =SUMIF('Septiembre 23'!$E$5:$E$23,$A3,'Septiembre 23'!$C$5:CQ$25) -> 10700 | BO3: =SUMIF('Octubre 23'!$E$5:$E$23,$A3,'Octubre 23'!$C$5:CQ$25) -> 10700 | BP3: =SUMIF('Noviembre 23'!$E$5:$E$23,$A3,'Noviembre 23'!$C$5:CQ$25) -> 10700 | BQ3: =SUMIF('Diciembre 23'!$E$5:$E$23,$A3,'Diciembre 23'!$C$5:CQ$25) -> 10700 | BR3: =SUMIF('Enero 24'!$E$5:$E$23,$A3,'Enero 24'!$C$5:CQ$25) -> 10700 | BS3: =SUMIF('Febrero 24'!$E$5:$E$23,$A3,'Febrero 24'!$C$5:CQ$25) -> 10700 | BT3: 11790 | BU3: =SUMIF('abril 24'!$E$5:$E$23,$A3,'abril 24'!$C$5:CQ$25) -> 10700 | BV3: =SUMIF('Mayo 24'!$E$5:$E$23,$A3,'Mayo 24'!$C$5:CQ$25) -> 14253 | BW3: =SUMIF('Junio 24'!$E$5:$E$23,$A3,'Junio 24'!$C$5:CQ$25) -> 14253 | BX3: =SUMIF('Julio 24'!$E$5:$E$23,$A3,'Julio 24'!$C$5:CQ$25) -> 14253 | BY3: =SUMIF('Agosto 24'!$E$5:$E$23,$A3,'Agosto 24'!$C$5:CQ$25) -> 14253 | BZ3: =SUMIF('Septiembre 24'!$E$5:$E$23,$A3,'Septiembre 24'!$C$5:CQ$25) -> 14253 | CA3: =SUMIF('Octubre 24'!$E$5:$E$23,$A3,'Octubre 24'!$C$5:CQ$25) -> 14253 | CB3: =SUMIF('Noviembre 24'!$E$5:$E$23,$A3,'Noviembre 24'!$C$5:CQ$25) -> 14253 | CC3: =SUMIF('Diciembre 24'!$E$5:$E$23,$A3,'Diciembre 24'!$C$5:CQ$25) -> 14253 | CD3: =SUMIF('Enero 25'!$E$5:$E$23,$A3,'Enero 25'!$C$5:CQ$25) -> 14253 | CE3: =SUMIF('febrero 25'!$E$5:$E$23,$A3,'febrero 25'!$C$5:CQ$25) -> 14253 | CF3: =SUMIF('marzo 25'!$E$5:$E$23,$A3,'marzo 25'!$C$5:CQ$25) -> 14253 | CG3: =SUMIF('abril 25'!$E$5:$E$23,$A3,'abril 25'!$C$5:CQ$25) -> 14253 | CH3: =SUMIF('Mayo 25'!$E$5:$E$23,$A3,'Mayo 25'!$C$5:CQ$25) -> 14253 | CI3: =SUMIF('Junio 25'!$E$5:$E$23,$A3,'Junio 25'!$C$5:CQ$25) -> 14253 | CJ3: =SUMIF('Julio 25'!$E$5:$E$23,$A3,'Julio 25'!$C$5:CQ$25) -> 14253 | CK3: =SUMIF('Agosto 25'!$E$5:$E$23,$A3,'Agosto 25'!$C$5:CQ$25) -> 14253 | CL3: =SUMIF('Septiembre 25'!$E$5:$E$23,$A3,'Septiembre 25'!$C$5:CQ$25) -> 14253 | CM3: =SUMIF('Octubre 25'!$E$5:$E$23,$A3,'Octubre 25'!$C$5:CQ$25) -> 14253 | CN3: =SUMIF('noviembre 25'!$E$5:$E$23,$A3,'noviembre 25'!$C$5:CQ$25) -> 14253
A4: Supermercado | B4: =MAX(BN4:ZZ4) -> 597487.52 | C4: =MIN(AK4:ZZ4) -> 0 | D4: =AVERAGE(AK4:ZZ4) -> 205213.37 | E4: =SUMIF(Agosto!$E$5:$E$25,$A4,Agosto!$C$5:$C$25) -> 323457 | F4: =SUMIF(Septiembre!$E$5:$E$25,$A4,Septiembre!$C$5:$C$25) -> 179594 | G4: =SUMIF(octubre!$E$5:E$25,$A4,octubre!$C$5:$C$25) -> 198576 | H4: =SUMIF(noviembre!$E$5:F$25,$A4,noviembre!$C$5:$C$25) -> 171902 | I4: =SUMIF(Diciembre!$E$5:CQ$25,$A4,Diciembre!$C$5:$C$25) -> 239690 | J4: =SUMIF(Enero!$E$5:E$25,$A4,Enero!$C$5:$C$25) -> 179779 | K4: =SUMIF(febrero!$E$5:$E$25,$A4,febrero!$C$5:CQ$25) -> 186244 | L4: =SUMIF(Marzo!$E$5:$E$25,$A4,Marzo!$C$5:CQ$25) -> 189515 | M4: =SUMIF(Abril!$E$5:$E$25,$A4,Abril!$C$5:CQ$25) -> 36309 | N4: =SUMIF(Mayo!$E$5:$E$25,$A4,Mayo!$C$5:CQ$25) -> 85000 | O4: =SUMIF(Junio!$E$5:$E$25,$A4,Junio!$C$5:CQ$25) -> 149585 | P4: =SUMIF(Julio!$E$5:$E$25,$A4,Julio!$C$5:CQ$25) -> 95516 | Q4: =SUMIF('Agosto 19'!$E$5:$E$23,$A4,'Agosto 19'!$C$5:CQ$25) -> 45000 | R4: =SUMIF('Septiembre 19'!$E$5:$E$23,$A4,'Septiembre 19'!$C$5:CQ$25) -> 80000 | S4: =SUMIF('Octubre 19'!$E$5:$E$23,$A4,'Octubre 19'!$C$5:CQ$25) -> 60000 | T4: =SUMIF('Noviembre 19'!$E$5:$E$23,$A4,'Noviembre 19'!$C$5:CQ$25) -> 37330 | U4: =SUMIF('Diciembre 19'!$E$5:$E$23,$A4,'Diciembre 19'!$C$5:CQ$25) -> 105268 | V4: =SUMIF('Enero 20'!$E$5:$E$23,$A4,'Enero 20'!$C$5:CQ$25) -> 105268 | W4: =SUMIF('Febrero 20'!$E$5:$E$23,$A4,'Febrero 20'!$C$5:CQ$25) -> 19765 | X4: =SUMIF('Marzo 20'!$E$5:$E$23,$A4,'Marzo 20'!$C$5:CQ$25) -> 79995 | Y4: =SUMIF('Abril 20'!$E$5:$E$23,$A4,'Abril 20'!$C$5:CQ$25) -> 253396 | Z4: =SUMIF('Mayo 20'!$E$5:$E$23,$A4,'Mayo 20'!$C$5:CQ$25) -> 200000 | AA4: =SUMIF('Junio 20'!$E$5:$E$23,$A4,'Junio 20'!$C$5:CQ$25) -> 233113 | AB4: =SUMIF('Julio 20'!$E$5:$E$23,$A4,'Julio 20'!$C$5:CQ$25) -> 187500 | AC4: =SUMIF('Agosto 20'!$E$5:$E$23,$A4,'Agosto 20'!$C$5:CQ$25) -> 120518 | AD4: =SUMIF('Septiembre 20'!$E$5:$E$23,$A4,'Septiembre 20'!$C$5:CQ$25) -> 230260 | AE4: =SUMIF('octubre 20'!$E$5:$E$23,$A4,'octubre 20'!$C$5:CQ$25) -> 143000 | AF4: =SUMIF('noviembre 20'!$E$5:$E$23,$A4,'noviembre 20'!$C$5:CQ$25) -> 115000 | AG4: =SUMIF('diciembre 20'!$E$5:$E$23,$A4,'diciembre 20'!$C$5:CQ$25) -> 76900 | AH4: =SUMIF('enero 21'!$E$5:$E$23,$A4,'enero 21'!$C$5:CQ$25) -> 115970 | AI4: =SUMIF('febrero 21'!$E$5:$E$23,$A4,'febrero 21'!$C$5:CQ$25) -> 119814 | AJ4: =SUMIF('marzo 21'!$E$5:$E$23,$A4,'marzo 21'!$C$5:CQ$25) -> 133000 | AK4: =SUMIF('abril 21'!$E$5:$E$23,$A4,'abril 21'!$C$5:CQ$25) -> 280400 | AL4: =SUMIF('mayo 21'!$E$5:$E$23,$A4,'mayo 21'!$C$5:CQ$25) -> 231334 | AM4: =SUMIF('Junio 21'!$E$5:$E$23,$A4,'Junio 21'!$C$5:CQ$25) -> 271789 | AN4: =SUMIF('Julio 21'!$E$5:$E$23,$A4,'Julio 21'!$C$5:CQ$25) -> 221452 | AO4: =SUMIF('Agosto 21'!$E$5:$E$23,$A4,'Agosto 21'!$C$5:CQ$25) -> 69710 | AP4: =SUMIF('Septiembre 21'!$E$5:$E$23,$A4,'Septiembre 21'!$C$5:CQ$25) -> 364000 | AQ4: =SUMIF('Octubre 21'!$E$5:$E$23,$A4,'Octubre 21'!$C$5:CQ$25) -> 154762 | AR4: =SUMIF('Noviembre 21'!$E$5:$E$23,$A4,'Noviembre 21'!$C$5:CQ$25) -> 183421 | AS4: =SUMIF('Diciembre 21'!$E$5:$E$23,$A4,'Noviembre 21'!$C$5:CQ$25) -> 183421 | AT4: =SUMIF('Enero 22'!$E$5:$E$23,$A4,'Enero 22'!$C$5:CQ$25) -> 140000 | AU4: =SUMIF('Febrero 22'!$E$5:$E$23,$A4,'Febrero 22'!$C$5:CQ$25) -> 40000 | AV4: =SUMIF('Marzo 22'!$E$5:$E$23,$A4,'Marzo 22'!$C$5:CQ$25) -> 308000 | AW4: =SUMIF('Abril 22'!$E$5:$E$23,$A4,'Abril 22'!$C$5:CQ$25) -> 108000 | AX4: =SUMIF('Mayo 22'!$E$5:$E$23,$A4,'Mayo 22'!$C$5:CQ$25) -> 180000 | AY4: =SUMIF('Junio 22'!$E$5:$E$23,$A4,'Junio 22'!$C$5:CQ$25) -> 100000 | AZ4: =SUMIF('Julio 22'!$E$5:$E$23,$A4,'Julio 22'!$C$5:CQ$25) -> 140000 | BA4: =SUMIF('Agosto 22'!$E$5:$E$23,$A4,'Agosto 22'!$C$5:CQ$25) -> 85000 | BB4: =SUMIF('septiembre 22'!$E$5:$E$23,$A4,'septiembre 22'!$C$5:CQ$25) -> 106000 | BC4: =SUMIF('octubre 22'!$E$5:$E$23,$A4,'octubre 22'!$C$5:CQ$25) -> 158000 | BD4: =SUMIF('noviembre 22'!$E$5:$E$23,$A4,'noviembre 22'!$C$5:CQ$25) -> 125000 | BE4: =SUMIF('diciembre 22'!$E$5:$E$23,$A4,'noviembre 22'!$C$5:CQ$25) -> 125000 | BF4: =SUMIF('Enero 23'!$E$5:$E$23,$A4,'Enero 23'!$C$5:CQ$25) -> 117000 | BG4: =SUMIF('Febrero 23'!$E$5:$E$23,$A4,'Febrero 23'!$C$5:CQ$25) -> 42000 | BH4: =SUMIF('Marzo 23'!$E$5:$E$23,$A4,'Marzo 23'!$C$5:CQ$25) -> 137835 | BI4: =SUMIF('Abril 23'!$E$5:$E$23,$A4,'Abril 23'!$C$5:CQ$25) -> 32600 | BJ4: =SUMIF('Mayo 23'!$E$5:$E$23,$A4,'Mayo 23'!$C$5:CQ$25) -> 140000 | BK4: =SUMIF('Junio 23'!$E$5:$E$23,$A4,'Junio 23'!$C$5:CQ$25) -> 140000 | BL4: =SUMIF('Julio 23'!$E$5:$E$23,$A4,'Julio 23'!$C$5:CQ$25) -> 200000 | BM4: =SUMIF('Agosto 23'!$E$5:$E$23,$A4,'Agosto 23'!$C$5:CQ$25) -> 130000 | BN4: =SUMIF('Septiembre 23'!$E$5:$E$23,$A4,'Septiembre 23'!$C$5:CQ$25) -> 160000 | BO4: =SUMIF('Octubre 23'!$E$5:$E$23,$A4,'Octubre 23'!$C$5:CQ$25) -> 160000 | BP4: =SUMIF('Noviembre 23'!$E$5:$E$23,$A4,'Noviembre 23'!$C$5:CQ$25) -> 160000 | BQ4: =SUMIF('Diciembre 23'!$E$5:$E$23,$A4,'Diciembre 23'!$C$5:CQ$25) -> 160000 | BR4: =SUMIF('Enero 24'!$E$5:$E$23,$A4,'Enero 24'!$C$5:CQ$25) -> 0 | BS4: =SUMIF('Febrero 24'!$E$5:$E$23,$A4,'Febrero 24'!$C$5:CQ$25) -> 70000 | BT4: =SUMIF('Marzo 24'!$E$5:$E$23,$A4,'Marzo 24'!$C$5:CQ$25) -> 70000 | BU4: =SUMIF('abril 24'!$E$5:$E$23,$A4,'abril 24'!$C$5:CQ$25) -> 380000 | BV4: =SUMIF('Mayo 24'!$E$5:$E$23,$A4,'Mayo 24'!$C$5:CQ$25) -> 304902.44 | BW4: =SUMIF('Junio 24'!$E$5:$E$23,$A4,'Junio 24'!$C$5:CQ$25) -> 322000 | BX4: =SUMIF('Julio 24'!$E$5:$E$23,$A4,'Julio 24'!$C$5:CQ$25) -> 112000 | BY4: =SUMIF('Agosto 24'!$E$5:$E$23,$A4,'Agosto 24'!$C$5:CQ$25) -> 321510 | BZ4: =SUMIF('Septiembre 24'!$E$5:$E$23,$A4,'Septiembre 24'!$C$5:CQ$25) -> 396000 | CA4: =SUMIF('Octubre 24'!$E$5:$E$23,$A4,'Octubre 24'!$C$5:CQ$25) -> 597487.52 | CB4: =SUMIF('Noviembre 24'!$E$5:$E$23,$A4,'Noviembre 24'!$C$5:CQ$25) -> 322000 | CC4: =SUMIF('Diciembre 24'!$E$5:$E$23,$A4,'Diciembre 24'!$C$5:CQ$25) -> 202000 | CD4: =SUMIF('Enero 25'!$E$5:$E$23,$A4,'Enero 25'!$C$5:CQ$25) -> 210000 | CE4: =SUMIF('febrero 25'!$E$5:$E$23,$A4,'febrero 25'!$C$5:CQ$25) -> 178000 | CF4: =SUMIF('marzo 25'!$E$5:$E$23,$A4,'marzo 25'!$C$5:CQ$25) -> 327000 | CG4: =SUMIF('abril 25'!$E$5:$E$23,$A4,'abril 25'!$C$5:CQ$25) -> 311000 | CH4: =SUMIF('Mayo 25'!$E$5:$E$23,$A4,'Mayo 25'!$C$5:CQ$25) -> 317500 | CI4: =SUMIF('Junio 25'!$E$5:$E$23,$A4,'Junio 25'!$C$5:CQ$25) -> 354825 | CJ4: =SUMIF('Julio 25'!$E$5:$E$23,$A4,'Julio 25'!$C$5:CQ$25) -> 298000 | CK4: =SUMIF('Agosto 25'!$E$5:$E$23,$A4,'Agosto 25'!$C$5:CQ$25) -> 326000 | CL4: =SUMIF('Septiembre 25'!$E$5:$E$23,$A4,'Septiembre 25'!$C$5:CQ$25) -> 324000 | CM4: =SUMIF('Octubre 25'!$E$5:$E$23,$A4,'Octubre 25'!$C$5:CQ$25) -> 324000 | CN4: =SUMIF('noviembre 25'!$E$5:$E$23,$A4,'noviembre 25'!$C$5:CQ$25) -> 269000
A5: Arriendo | B5: =MAX(BN5:ZZ5) -> 640662.16 | C5: =MIN(AK5:ZZ5) -> 466000 | D5: =AVERAGE(AK5:ZZ5) -> 615770.03 | E5: =SUMIF(Agosto!$E$5:$E$25,$A5,Agosto!$C$5:$C$25) -> 580000 | F5: =SUMIF(Septiembre!$E$5:$E$25,$A5,Septiembre!$C$5:$C$25) -> 580000 | G5: =SUMIF(octubre!$E$5:E$25,$A5,octubre!$C$5:$C$25) -> 580000 | H5: =SUMIF(noviembre!$E$5:F$25,$A5,noviembre!$C$5:$C$25) -> 580000 | I5: =SUMIF(Diciembre!$E$5:CQ$25,$A5,Diciembre!$C$5:$C$25) -> 580000 | J5: =SUMIF(Enero!$E$5:E$25,$A5,Enero!$C$5:$C$25) -> 580000 | K5: =SUMIF(febrero!$E$5:$E$25,$A5,febrero!$C$5:CQ$25) -> 586380 | L5: =SUMIF(Marzo!$E$5:$E$25,$A5,Marzo!$C$5:CQ$25) -> 586380 | M5: =SUMIF(Abril!$E$5:$E$25,$A5,Abril!$C$5:CQ$25) -> 586380 | N5: =SUMIF(Mayo!$E$5:$E$25,$A5,Mayo!$C$5:CQ$25) -> 586380 | O5: =SUMIF(Junio!$E$5:$E$25,$A5,Junio!$C$5:CQ$25) -> 586380 | P5: =SUMIF(Julio!$E$5:$E$25,$A5,Julio!$C$5:CQ$25) -> 586380 | Q5: =SUMIF('Agosto 19'!$E$5:$E$23,$A5,'Agosto 19'!$C$5:CQ$25) -> 586380 | R5: =SUMIF('Septiembre 19'!$E$5:$E$23,$A5,'Septiembre 19'!$C$5:CQ$25) -> 586380 | S5: =SUMIF('Octubre 19'!$E$5:$E$23,$A5,'Octubre 19'!$C$5:CQ$25) -> 586380 | T5: =SUMIF('Noviembre 19'!$E$5:$E$23,$A5,'Noviembre 19'!$C$5:CQ$25) -> 586380 | U5: =SUMIF('Diciembre 19'!$E$5:$E$23,$A5,'Diciembre 19'!$C$5:CQ$25) -> 586380 | V5: =SUMIF('Enero 20'!$E$5:$E$23,$A5,'Enero 20'!$C$5:CQ$25) -> 586380 | W5: =SUMIF('Febrero 20'!$E$5:$E$23,$A5,'Febrero 20'!$C$5:CQ$25) -> 586380 | X5: =SUMIF('Marzo 20'!$E$5:$E$23,$A5,'Marzo 20'!$C$5:CQ$25) -> 586380 | Y5: =SUMIF('Abril 20'!$E$5:$E$23,$A5,'Abril 20'!$C$5:CQ$25) -> 586380 | Z5: =SUMIF('Mayo 20'!$E$5:$E$23,$A5,'Mayo 20'!$C$5:CQ$25) -> 586380 | AA5: =SUMIF('Junio 20'!$E$5:$E$23,$A5,'Junio 20'!$C$5:CQ$25) -> 586380 | AB5: =SUMIF('Julio 20'!$E$5:$E$23,$A5,'Julio 20'!$C$5:CQ$25) -> 586380 | AC5: =SUMIF('Agosto 20'!$E$5:$E$23,$A5,'Agosto 20'!$C$5:CQ$25) -> 586380 | AD5: =SUMIF('Septiembre 20'!$E$5:$E$23,$A5,'Septiembre 20'!$C$5:CQ$25) -> 586380 | AE5: =SUMIF('octubre 20'!$E$5:$E$23,$A5,'octubre 20'!$C$5:CQ$25) -> 586380 | AF5: =SUMIF('noviembre 20'!$E$5:$E$23,$A5,'noviembre 20'!$C$5:CQ$25) -> 586380 | AG5: =SUMIF('diciembre 20'!$E$5:$E$23,$A5,'diciembre 20'!$C$5:CQ$25) -> 586380 | AH5: =SUMIF('enero 21'!$E$5:$E$23,$A5,'enero 21'!$C$5:CQ$25) -> 586380 | AI5: =SUMIF('febrero 21'!$E$5:$E$23,$A5,'febrero 21'!$C$5:CQ$25) -> 550000 | AJ5: =SUMIF('marzo 21'!$E$5:$E$23,$A5,'marzo 21'!$C$5:CQ$25) -> 550000 | AK5: =SUMIF('abril 21'!$E$5:$E$23,$A5,'abril 21'!$C$5:CQ$25) -> 550000 | AL5: =SUMIF('mayo 21'!$E$5:$E$23,$A5,'mayo 21'!$C$5:CQ$25) -> 550000 | AM5: =SUMIF('Junio 21'!$E$5:$E$23,$A5,'Junio 21'!$C$5:CQ$25) -> 466000 | AN5: =SUMIF('Julio 21'!$E$5:$E$23,$A5,'Julio 21'!$C$5:CQ$25) -> 466000 | AO5: =SUMIF('Agosto 21'!$E$5:$E$23,$A5,'Agosto 21'!$C$5:CQ$25) -> 466000 | AP5: =SUMIF('Septiembre 21'!$E$5:$E$23,$A5,'Septiembre 21'!$C$5:CQ$25) -> 466000 | AQ5: =SUMIF('Octubre 21'!$E$5:$E$23,$A5,'Octubre 21'!$C$5:CQ$25) -> 466000 | AR5: =SUMIF('Noviembre 21'!$E$5:$E$23,$A5,'Noviembre 21'!$C$5:CQ$25) -> 471000 | AS5: =SUMIF('Diciembre 21'!$E$5:$E$23,$A5,'Noviembre 21'!$C$5:CQ$25) -> 471000 | AT5: =SUMIF('Enero 22'!$E$5:$E$23,$A5,'Enero 22'!$C$5:CQ$25) -> 640662.16 | AU5: =SUMIF('Febrero 22'!$E$5:$E$23,$A5,'Febrero 22'!$C$5:CQ$25) -> 640662.16 | AV5: =SUMIF('Marzo 22'!$E$5:$E$23,$A5,'Marzo 22'!$C$5:CQ$25) -> 640662.16 | AW5: =SUMIF('Abril 22'!$E$5:$E$23,$A5,'Abril 22'!$C$5:CQ$25) -> 640662.16 | AX5: =SUMIF('Mayo 22'!$E$5:$E$23,$A5,'Mayo 22'!$C$5:CQ$25) -> 640662.16 | AY5: =SUMIF('Junio 22'!$E$5:$E$23,$A5,'Junio 22'!$C$5:CQ$25) -> 640662.16 | AZ5: =SUMIF('Julio 22'!$E$5:$E$23,$A5,'Julio 22'!$C$5:CQ$25) -> 640662.16 | BA5: =SUMIF('Agosto 22'!$E$5:$E$23,$A5,'Agosto 22'!$C$5:CQ$25) -> 640662.16 | BB5: =SUMIF('septiembre 22'!$E$5:$E$23,$A5,'septiembre 22'!$C$5:CQ$25) -> 640662.16 | BC5: =SUMIF('octubre 22'!$E$5:$E$23,$A5,'octubre 22'!$C$5:CQ$25) -> 640662.16 | BD5: =SUMIF('noviembre 22'!$E$5:$E$23,$A5,'noviembre 22'!$C$5:CQ$25) -> 640662.16 | BE5: =SUMIF('diciembre 22'!$E$5:$E$23,$A5,'noviembre 22'!$C$5:CQ$25) -> 640662.16 | BF5: =SUMIF('Enero 23'!$E$5:$E$23,$A5,'Enero 23'!$C$5:CQ$25) -> 640662.16 | BG5: =SUMIF('Febrero 23'!$E$5:$E$23,$A5,'Febrero 23'!$C$5:CQ$25) -> 640662.16 | BH5: =SUMIF('Marzo 23'!$E$5:$E$23,$A5,'Marzo 23'!$C$5:CQ$25) -> 640662.16 | BI5: =SUMIF('Abril 23'!$E$5:$E$23,$A5,'Abril 23'!$C$5:CQ$25) -> 640662.16 | BJ5: =SUMIF('Mayo 23'!$E$5:$E$23,$A5,'Mayo 23'!$C$5:CQ$25) -> 640662.16 | BK5: =SUMIF('Junio 23'!$E$5:$E$23,$A5,'Junio 23'!$C$5:CQ$25) -> 640662.16 | BL5: =SUMIF('Julio 23'!$E$5:$E$23,$A5,'Julio 23'!$C$5:CQ$25) -> 640662.16 | BM5: =SUMIF('Agosto 23'!$E$5:$E$23,$A5,'Agosto 23'!$C$5:CQ$25) -> 640662.16 | BN5: =SUMIF('Septiembre 23'!$E$5:$E$23,$A5,'Septiembre 23'!$C$5:CQ$25) -> 640662.16 | BO5: =SUMIF('Octubre 23'!$E$5:$E$23,$A5,'Octubre 23'!$C$5:CQ$25) -> 640662.16 | BP5: =SUMIF('Noviembre 23'!$E$5:$E$23,$A5,'Noviembre 23'!$C$5:CQ$25) -> 640662.16 | BQ5: =SUMIF('Diciembre 23'!$E$5:$E$23,$A5,'Diciembre 23'!$C$5:CQ$25) -> 640662.16 | BR5: =SUMIF('Enero 24'!$E$5:$E$23,$A5,'Enero 24'!$C$5:CQ$25) -> 640662.16 | BS5: =SUMIF('Febrero 24'!$E$5:$E$23,$A5,'Febrero 24'!$C$5:CQ$25) -> 640662.16 | BT5: =SUMIF('Marzo 24'!$E$5:$E$23,$A5,'Marzo 24'!$C$5:CQ$25) -> 640662.16 | BU5: =SUMIF('abril 24'!$E$5:$E$23,$A5,'abril 24'!$C$5:CQ$25) -> 640662.16 | BV5: =SUMIF('Mayo 24'!$E$5:$E$23,$A5,'Mayo 24'!$C$5:CQ$25) -> 640662.16 | BW5: =SUMIF('Junio 24'!$E$5:$E$23,$A5,'Junio 24'!$C$5:CQ$25) -> 640662.16 | BX5: =SUMIF('Julio 24'!$E$5:$E$23,$A5,'Julio 24'!$C$5:CQ$25) -> 640662.16 | BY5: =SUMIF('Agosto 24'!$E$5:$E$23,$A5,'Agosto 24'!$C$5:CQ$25) -> 640662.16 | BZ5: =SUMIF('Septiembre 24'!$E$5:$E$23,$A5,'Septiembre 24'!$C$5:CQ$25) -> 640662.16 | CA5: =SUMIF('Octubre 24'!$E$5:$E$23,$A5,'Octubre 24'!$C$5:CQ$25) -> 640662.16 | CB5: =SUMIF('Noviembre 24'!$E$5:$E$23,$A5,'Noviembre 24'!$C$5:CQ$25) -> 640662.16 | CC5: =SUMIF('Diciembre 24'!$E$5:$E$23,$A5,'Diciembre 24'!$C$5:CQ$25) -> 640662.16 | CD5: =SUMIF('Enero 25'!$E$5:$E$23,$A5,'Enero 25'!$C$5:CQ$25) -> 640662.16 | CE5: =SUMIF('febrero 25'!$E$5:$E$23,$A5,'febrero 25'!$C$5:CQ$25) -> 640662.16 | CF5: =SUMIF('marzo 25'!$E$5:$E$23,$A5,'marzo 25'!$C$5:CQ$25) -> 640662.16 | CG5: =SUMIF('abril 25'!$E$5:$E$23,$A5,'abril 25'!$C$5:CQ$25) -> 640662.16 | CH5: =SUMIF('Mayo 25'!$E$5:$E$23,$A5,'Mayo 25'!$C$5:CQ$25) -> 640662.16 | CI5: =SUMIF('Junio 25'!$E$5:$E$23,$A5,'Junio 25'!$C$5:CQ$25) -> 640662.16 | CJ5: =SUMIF('Julio 25'!$E$5:$E$23,$A5,'Julio 25'!$C$5:CQ$25) -> 640662.16 | CK5: =SUMIF('Agosto 25'!$E$5:$E$23,$A5,'Agosto 25'!$C$5:CQ$25) -> 640662.16 | CL5: =SUMIF('Septiembre 25'!$E$5:$E$23,$A5,'Septiembre 25'!$C$5:CQ$25) -> 640662.16 | CM5: =SUMIF('Octubre 25'!$E$5:$E$23,$A5,'Octubre 25'!$C$5:CQ$25) -> 640662.16 | CN5: =SUMIF('noviembre 25'!$E$5:$E$23,$A5,'noviembre 25'!$C$5:CQ$25) -> 640662.16
A6: Gastos comunes | B6: =MAX(BN6:ZZ6) -> 270000 | C6: =MIN(AK6:ZZ6) -> 144056 | D6: =AVERAGE(AK6:ZZ6) -> 202150.46 | E6: =SUMIF(Agosto!$E$5:$E$25,$A6,Agosto!$C$5:$C$25) -> 150000 | F6: =SUMIF(Septiembre!$E$5:$E$25,$A6,Septiembre!$C$5:$C$25) -> 163601 | G6: =SUMIF(octubre!$E$5:E$25,$A6,octubre!$C$5:$C$25) -> 129087 | H6: =SUMIF(noviembre!$E$5:F$25,$A6,noviembre!$C$5:$C$25) -> 147120 | I6: =SUMIF(Diciembre!$E$5:CQ$25,$A6,Diciembre!$C$5:$C$25) -> 134136 | J6: =SUMIF(Enero!$E$5:E$25,$A6,Enero!$C$5:$C$25) -> 114748 | K6: =SUMIF(febrero!$E$5:$E$25,$A6,febrero!$C$5:CQ$25) -> 115626 | L6: =SUMIF(Marzo!$E$5:$E$25,$A6,Marzo!$C$5:CQ$25) -> 125210 | M6: =SUMIF(Abril!$E$5:$E$25,$A6,Abril!$C$5:CQ$25) -> 145000 | N6: =SUMIF(Mayo!$E$5:$E$25,$A6,Mayo!$C$5:CQ$25) -> 141000 | O6: =SUMIF(Junio!$E$5:$E$25,$A6,Junio!$C$5:CQ$25) -> 126159 | P6: =SUMIF(Julio!$E$5:$E$25,$A6,Julio!$C$5:CQ$25) -> 157201 | Q6: =SUMIF('Agosto 19'!$E$5:$E$23,$A6,'Agosto 19'!$C$5:CQ$25) -> 174538 | R6: =SUMIF('Septiembre 19'!$E$5:$E$23,$A6,'Septiembre 19'!$C$5:CQ$25) -> 137822 | S6: =SUMIF('Octubre 19'!$E$5:$E$23,$A6,'Octubre 19'!$C$5:CQ$25) -> 192128 | T6: =SUMIF('Noviembre 19'!$E$5:$E$23,$A6,'Noviembre 19'!$C$5:CQ$25) -> 129148 | U6: =SUMIF('Diciembre 19'!$E$5:$E$23,$A6,'Diciembre 19'!$C$5:CQ$25) -> 111989 | V6: =SUMIF('Enero 20'!$E$5:$E$23,$A6,'Enero 20'!$C$5:CQ$25) -> 124389 | W6: =SUMIF('Febrero 20'!$E$5:$E$23,$A6,'Febrero 20'!$C$5:CQ$25) -> 96394 | X6: =SUMIF('Marzo 20'!$E$5:$E$23,$A6,'Marzo 20'!$C$5:CQ$25) -> 110457 | Y6: =SUMIF('Abril 20'!$E$5:$E$23,$A6,'Abril 20'!$C$5:CQ$25) -> 110355 | Z6: =SUMIF('Mayo 20'!$E$5:$E$23,$A6,'Mayo 20'!$C$5:CQ$25) -> 116014 | AA6: =SUMIF('Junio 20'!$E$5:$E$23,$A6,'Junio 20'!$C$5:CQ$25) -> 120891 | AB6: =SUMIF('Julio 20'!$E$5:$E$23,$A6,'Julio 20'!$C$5:CQ$25) -> 146308 | AC6: =SUMIF('Agosto 20'!$E$5:$E$23,$A6,'Agosto 20'!$C$5:CQ$25) -> 166549 | AD6: =SUMIF('Septiembre 20'!$E$5:$E$23,$A6,'Septiembre 20'!$C$5:CQ$25) -> 140181 | AE6: =SUMIF('octubre 20'!$E$5:$E$23,$A6,'octubre 20'!$C$5:CQ$25) -> 121609 | AF6: =SUMIF('noviembre 20'!$E$5:$E$23,$A6,'noviembre 20'!$C$5:CQ$25) -> 117535 | AG6: =SUMIF('diciembre 20'!$E$5:$E$23,$A6,'diciembre 20'!$C$5:CQ$25) -> 126117 | AH6: =SUMIF('enero 21'!$E$5:$E$23,$A6,'enero 21'!$C$5:CQ$25) -> 138100 | AI6: =SUMIF('febrero 21'!$E$5:$E$23,$A6,'febrero 21'!$C$5:CQ$25) -> 116051 | AJ6: =SUMIF('marzo 21'!$E$5:$E$23,$A6,'marzo 21'!$C$5:CQ$25) -> 135000 | AK6: =SUMIF('abril 21'!$E$5:$E$23,$A6,'abril 21'!$C$5:CQ$25) -> 144056 | AL6: =SUMIF('mayo 21'!$E$5:$E$23,$A6,'mayo 21'!$C$5:CQ$25) -> 161513 | AM6: =SUMIF('Junio 21'!$E$5:$E$23,$A6,'Junio 21'!$C$5:CQ$25) -> 171383 | AN6: =SUMIF('Julio 21'!$E$5:$E$23,$A6,'Julio 21'!$C$5:CQ$25) -> 162615 | AO6: =SUMIF('Agosto 21'!$E$5:$E$23,$A6,'Agosto 21'!$C$5:CQ$25) -> 174074 | AP6: =SUMIF('Septiembre 21'!$E$5:$E$23,$A6,'Septiembre 21'!$C$5:CQ$25) -> 177519 | AQ6: =SUMIF('Octubre 21'!$E$5:$E$23,$A6,'Octubre 21'!$C$5:CQ$25) -> 168795 | AR6: =SUMIF('Noviembre 21'!$E$5:$E$23,$A6,'Noviembre 21'!$C$5:CQ$25) -> 180954 | AS6: =SUMIF('Diciembre 21'!$E$5:$E$23,$A6,'Noviembre 21'!$C$5:CQ$25) -> 180954 | AT6: =SUMIF('Enero 22'!$E$5:$E$23,$A6,'Enero 22'!$C$5:CQ$25) -> 156000 | AU6: =SUMIF('Febrero 22'!$E$5:$E$23,$A6,'Febrero 22'!$C$5:CQ$25) -> 167592 | AV6: =SUMIF('Marzo 22'!$E$5:$E$23,$A6,'Marzo 22'!$C$5:CQ$25) -> 177531 | AW6: =SUMIF('Abril 22'!$E$5:$E$23,$A6,'Abril 22'!$C$5:CQ$25) -> 168060 | AX6: =SUMIF('Mayo 22'!$E$5:$E$23,$A6,'Mayo 22'!$C$5:CQ$25) -> 172675 | AY6: =SUMIF('Junio 22'!$E$5:$E$23,$A6,'Junio 22'!$C$5:CQ$25) -> 173865 | AZ6: =SUMIF('Julio 22'!$E$5:$E$23,$A6,'Julio 22'!$C$5:CQ$25) -> 178915 | BA6: =SUMIF('Agosto 22'!$E$5:$E$23,$A6,'Agosto 22'!$C$5:CQ$25) -> 181886 | BB6: =SUMIF('septiembre 22'!$E$5:$E$23,$A6,'septiembre 22'!$C$5:CQ$25) -> 181886 | BC6: =SUMIF('octubre 22'!$E$5:$E$23,$A6,'octubre 22'!$C$5:CQ$25) -> 199000 | BD6: =SUMIF('noviembre 22'!$E$5:$E$23,$A6,'noviembre 22'!$C$5:CQ$25) -> 178421 | BE6: =SUMIF('diciembre 22'!$E$5:$E$23,$A6,'noviembre 22'!$C$5:CQ$25) -> 178421 | BF6: =SUMIF('Enero 23'!$E$5:$E$23,$A6,'Enero 23'!$C$5:CQ$25) -> 189369 | BG6: =SUMIF('Febrero 23'!$E$5:$E$23,$A6,'Febrero 23'!$C$5:CQ$25) -> 172569 | BH6: =SUMIF('Marzo 23'!$E$5:$E$23,$A6,'Marzo 23'!$C$5:CQ$25) -> 197555 | BI6: =SUMIF('Abril 23'!$E$5:$E$23,$A6,'Abril 23'!$C$5:CQ$25) -> 184711 | BJ6: =SUMIF('Mayo 23'!$E$5:$E$23,$A6,'Mayo 23'!$C$5:CQ$25) -> 194071 | BK6: =SUMIF('Junio 23'!$E$5:$E$23,$A6,'Junio 23'!$C$5:CQ$25) -> 184071 | BL6: =SUMIF('Julio 23'!$E$5:$E$23,$A6,'Julio 23'!$C$5:CQ$25) -> 177929 | BM6: =SUMIF('Agosto 23'!$E$5:$E$23,$A6,'Agosto 23'!$C$5:CQ$25) -> 209199 | BN6: =SUMIF('Septiembre 23'!$E$5:$E$23,$A6,'Septiembre 23'!$C$5:CQ$25) -> 208199 | BO6: =SUMIF('Octubre 23'!$E$5:$E$23,$A6,'Octubre 23'!$C$5:CQ$25) -> 214783 | BP6: =SUMIF('Noviembre 23'!$E$5:$E$23,$A6,'Noviembre 23'!$C$5:CQ$25) -> 218783 | BQ6: =SUMIF('Diciembre 23'!$E$5:$E$23,$A6,'Diciembre 23'!$C$5:CQ$25) -> 235877 | BR6: =SUMIF('Enero 24'!$E$5:$E$23,$A6,'Enero 24'!$C$5:CQ$25) -> 225877 | BS6: =SUMIF('Febrero 24'!$E$5:$E$23,$A6,'Febrero 24'!$C$5:CQ$25) -> 225877 | BT6: =SUMIF('Marzo 24'!$E$5:$E$23,$A6,'Marzo 24'!$C$5:CQ$25) -> 230877 | BU6: =SUMIF('abril 24'!$E$5:$E$23,$A6,'abril 24'!$C$5:CQ$25) -> 216000 | BV6: =SUMIF('Mayo 24'!$E$5:$E$23,$A6,'Mayo 24'!$C$5:CQ$25) -> 226964 | BW6: =SUMIF('Junio 24'!$E$5:$E$23,$A6,'Junio 24'!$C$5:CQ$25) -> 234964 | BX6: =SUMIF('Julio 24'!$E$5:$E$23,$A6,'Julio 24'!$C$5:CQ$25) -> 252000 | BY6: =SUMIF('Agosto 24'!$E$5:$E$23,$A6,'Agosto 24'!$C$5:CQ$25) -> 251000 | BZ6: =SUMIF('Septiembre 24'!$E$5:$E$23,$A6,'Septiembre 24'!$C$5:CQ$25) -> 252000 | CA6: =SUMIF('Octubre 24'!$E$5:$E$23,$A6,'Octubre 24'!$C$5:CQ$25) -> 227000 | CB6: =SUMIF('Noviembre 24'!$E$5:$E$23,$A6,'Noviembre 24'!$C$5:CQ$25) -> 250000 | CC6: =SUMIF('Diciembre 24'!$E$5:$E$23,$A6,'Diciembre 24'!$C$5:CQ$25) -> 250000 | CD6: =SUMIF('Enero 25'!$E$5:$E$23,$A6,'Enero 25'!$C$5:CQ$25) -> 217636 | CE6: =SUMIF('febrero 25'!$E$5:$E$23,$A6,'febrero 25'!$C$5:CQ$25) -> 195000 | CF6: =SUMIF('marzo 25'!$E$5:$E$23,$A6,'marzo 25'!$C$5:CQ$25) -> 181000 | CG6: =SUMIF('abril 25'!$E$5:$E$23,$A6,'abril 25'!$C$5:CQ$25) -> 210000 | CH6: =SUMIF('Mayo 25'!$E$5:$E$23,$A6,'Mayo 25'!$C$5:CQ$25) -> 240000 | CI6: =SUMIF('Junio 25'!$E$5:$E$23,$A6,'Junio 25'!$C$5:CQ$25) -> 196000 | CJ6: =SUMIF('Julio 25'!$E$5:$E$23,$A6,'Julio 25'!$C$5:CQ$25) -> 225000 | CK6: =SUMIF('Agosto 25'!$E$5:$E$23,$A6,'Agosto 25'!$C$5:CQ$25) -> 270000 | CL6: =SUMIF('Septiembre 25'!$E$5:$E$23,$A6,'Septiembre 25'!$C$5:CQ$25) -> 240000 | CM6: =SUMIF('Octubre 25'!$E$5:$E$23,$A6,'Octubre 25'!$C$5:CQ$25) -> 240000 | CN6: =SUMIF('noviembre 25'!$E$5:$E$23,$A6,'noviembre 25'!$C$5:CQ$25) -> 240000
A7: Nana | B7: =MAX(BN7:ZZ7) -> 111000 | C7: =MIN(AK7:ZZ7) -> 0 | D7: =AVERAGE(AK7:ZZ7) -> 62428.571 | E7: =SUMIF(Agosto!$E$5:$E$25,$A7,Agosto!$C$5:$C$25) -> 0 | F7: =SUMIF(Septiembre!$E$5:$E$25,$A7,Septiembre!$C$5:$C$25) -> 0 | G7: =SUMIF(octubre!$E$5:E$25,$A7,octubre!$C$5:$C$25) -> 65000 | H7: =SUMIF(noviembre!$E$5:F$25,$A7,noviembre!$C$5:$C$25) -> 35000 | I7: =SUMIF(Diciembre!$E$5:CQ$25,$A7,Diciembre!$C$5:$C$25) -> 65000 | J7: =SUMIF(Enero!$E$5:E$25,$A7,Enero!$C$5:$C$25) -> 104175 | K7: =SUMIF(febrero!$E$5:$E$25,$A7,febrero!$C$5:CQ$25) -> 80000 | L7: =SUMIF(Marzo!$E$5:$E$25,$A7,Marzo!$C$5:CQ$25) -> 80000 | M7: =SUMIF(Abril!$E$5:$E$25,$A7,Abril!$C$5:CQ$25) -> 80000 | N7: =SUMIF(Mayo!$E$5:$E$25,$A7,Mayo!$C$5:CQ$25) -> 60000 | O7: =SUMIF(Junio!$E$5:$E$25,$A7,Junio!$C$5:CQ$25) -> 40000 | P7: =SUMIF(Julio!$E$5:$E$25,$A7,Julio!$C$5:CQ$25) -> 40000 | Q7: =SUMIF('Agosto 19'!$E$5:$E$23,$A7,'Agosto 19'!$C$5:CQ$25) -> 60000 | R7: =SUMIF('Septiembre 19'!$E$5:$E$23,$A7,'Septiembre 19'!$C$5:CQ$25) -> 60000 | S7: =SUMIF('Octubre 19'!$E$5:$E$23,$A7,'Octubre 19'!$C$5:CQ$25) -> 20000 | T7: =SUMIF('Noviembre 19'!$E$5:$E$23,$A7,'Noviembre 19'!$C$5:CQ$25) -> 40000 | U7: =SUMIF('Diciembre 19'!$E$5:$E$23,$A7,'Diciembre 19'!$C$5:CQ$25) -> 40000 | V7: =SUMIF('Enero 20'!$E$5:$E$23,$A7,'Enero 20'!$C$5:CQ$25) -> 50000 | W7: =SUMIF('Febrero 20'!$E$5:$E$23,$A7,'Febrero 20'!$C$5:CQ$25) -> 40000 | X7: =SUMIF('Marzo 20'!$E$5:$E$23,$A7,'Marzo 20'!$C$5:CQ$25) -> 40000 | Y7: =SUMIF('Abril 20'!$E$5:$E$23,$A7,'Abril 20'!$C$5:CQ$25) -> 0 | Z7: =SUMIF('Mayo 20'!$E$5:$E$23,$A7,'Mayo 20'!$C$5:CQ$25) -> 0 | AA7: 0 | AB7: =SUMIF('Julio 20'!$E$5:$E$23,$A7,'Julio 20'!$C$5:CQ$25) -> 60000 | AC7: =SUMIF('Agosto 20'!$E$5:$E$23,$A7,'Agosto 20'!$C$5:CQ$25) -> 60000 | AD7: =SUMIF('Septiembre 20'!$E$5:$E$23,$A7,'Septiembre 20'!$C$5:CQ$25) -> 60000 | AE7: =SUMIF('octubre 20'!$E$5:$E$23,$A7,'octubre 20'!$C$5:CQ$25) -> 0 | AF7: =SUMIF('noviembre 20'!$E$5:$E$23,$A7,'noviembre 20'!$C$5:CQ$25) -> 0 | AG7: =SUMIF('diciembre 20'!$E$5:$E$23,$A7,'diciembre 20'!$C$5:CQ$25) -> 0 | AH7: =SUMIF('enero 21'!$E$5:$E$23,$A7,'enero 21'!$C$5:CQ$25) -> 0 | AI7: =SUMIF('febrero 21'!$E$5:$E$23,$A7,'febrero 21'!$C$5:CQ$25) -> 0 | AJ7: =SUMIF('marzo 21'!$E$5:$E$23,$A7,'marzo 21'!$C$5:CQ$25) -> 0 | AK7: =SUMIF('abril 21'!$E$5:$E$23,$A7,'abril 21'!$C$5:CQ$25) -> 0 | AL7: =SUMIF('mayo 21'!$E$5:$E$23,$A7,'mayo 21'!$C$5:CQ$25) -> 0 | AM7: =SUMIF('Junio 21'!$E$5:$E$23,$A7,'Junio 21'!$C$5:CQ$25) -> 0 | AN7: =SUMIF('Julio 21'!$E$5:$E$23,$A7,'Julio 21'!$C$5:CQ$25) -> 0 | AO7: =SUMIF('Agosto 21'!$E$5:$E$23,$A7,'Agosto 21'!$C$5:CQ$25) -> 0 | AP7: =SUMIF('Septiembre 21'!$E$5:$E$23,$A7,'Septiembre 21'!$C$5:CQ$25) -> 0 | AQ7: =SUMIF('Octubre 21'!$E$5:$E$23,$A7,'Octubre 21'!$C$5:CQ$25) -> 0 | AR7: =SUMIF('Noviembre 21'!$E$5:$E$23,$A7,'Noviembre 21'!$C$5:CQ$25) -> 0 | AS7: =SUMIF('Diciembre 21'!$E$5:$E$23,$A7,'Noviembre 21'!$C$5:CQ$25) -> 0 | AT7: =SUMIF('Enero 22'!$E$5:$E$23,$A7,'Enero 22'!$C$5:CQ$25) -> 100000 | AU7: =SUMIF('Febrero 22'!$E$5:$E$23,$A7,'Febrero 22'!$C$5:CQ$25) -> 105000 | AV7: =SUMIF('Marzo 22'!$E$5:$E$23,$A7,'Marzo 22'!$C$5:CQ$25) -> 100000 | AW7: =SUMIF('Abril 22'!$E$5:$E$23,$A7,'Abril 22'!$C$5:CQ$25) -> 100000 | AX7: =SUMIF('Mayo 22'!$E$5:$E$23,$A7,'Mayo 22'!$C$5:CQ$25) -> 100000 | AY7: =SUMIF('Junio 22'!$E$5:$E$23,$A7,'Junio 22'!$C$5:CQ$25) -> 125000 | AZ7: =SUMIF('Julio 22'!$E$5:$E$23,$A7,'Julio 22'!$C$5:CQ$25) -> 125000 | BA7: =SUMIF('Agosto 22'!$E$5:$E$23,$A7,'Agosto 22'!$C$5:CQ$25) -> 100000 | BB7: =SUMIF('septiembre 22'!$E$5:$E$23,$A7,'septiembre 22'!$C$5:CQ$25) -> 150000 | BC7: =SUMIF('octubre 22'!$E$5:$E$23,$A7,'octubre 22'!$C$5:CQ$25) -> 150000 | BD7: =SUMIF('noviembre 22'!$E$5:$E$23,$A7,'noviembre 22'!$C$5:CQ$25) -> 150000 | BE7: =SUMIF('diciembre 22'!$E$5:$E$23,$A7,'noviembre 22'!$C$5:CQ$25) -> 150000 | BF7: =SUMIF('Enero 23'!$E$5:$E$23,$A7,'Enero 23'!$C$5:CQ$25) -> 150000 | BG7: =SUMIF('Febrero 23'!$E$5:$E$23,$A7,'Febrero 23'!$C$5:CQ$25) -> 150000 | BH7: =SUMIF('Marzo 23'!$E$5:$E$23,$A7,'Marzo 23'!$C$5:CQ$25) -> 150000 | BI7: =SUMIF('Abril 23'!$E$5:$E$23,$A7,'Abril 23'!$C$5:CQ$25) -> 0 | BJ7: =SUMIF('Mayo 23'!$E$5:$E$23,$A7,'Mayo 23'!$C$5:CQ$25) -> 0 | BK7: =SUMIF('Junio 23'!$E$5:$E$23,$A7,'Junio 23'!$C$5:CQ$25) -> 0 | BL7: =SUMIF('Julio 23'!$E$5:$E$23,$A7,'Julio 23'!$C$5:CQ$25) -> 0 | BM7: =SUMIF('Agosto 23'!$E$5:$E$23,$A7,'Agosto 23'!$C$5:CQ$25) -> 0 | BN7: =SUMIF('Septiembre 23'!$E$5:$E$23,$A7,'Septiembre 23'!$C$5:CQ$25) -> 0 | BO7: =SUMIF('Octubre 23'!$E$5:$E$23,$A7,'Octubre 23'!$C$5:CQ$25) -> 0 | BP7: =SUMIF('Noviembre 23'!$E$5:$E$23,$A7,'Noviembre 23'!$C$5:CQ$25) -> 0 | BQ7: =SUMIF('Diciembre 23'!$E$5:$E$23,$A7,'Diciembre 23'!$C$5:CQ$25) -> 0 | BR7: =SUMIF('Enero 24'!$E$5:$E$23,$A7,'Enero 24'!$C$5:CQ$25) -> 0 | BS7: =SUMIF('Febrero 24'!$E$5:$E$23,$A7,'Febrero 24'!$C$5:CQ$25) -> 0 | BT7: =SUMIF('Marzo 24'!$E$5:$E$23,$A7,'Marzo 24'!$C$5:CQ$25) -> 0 | BU7: =SUMIF('abril 24'!$E$5:$E$23,$A7,'abril 24'!$C$5:CQ$25) -> 37000 | BV7: =SUMIF('Mayo 24'!$E$5:$E$23,$A7,'Mayo 24'!$C$5:CQ$25) -> 74000 | BW7: =SUMIF('Junio 24'!$E$5:$E$23,$A7,'Junio 24'!$C$5:CQ$25) -> 74000 | BX7: =SUMIF('Julio 24'!$E$5:$E$23,$A7,'Julio 24'!$C$5:CQ$25) -> 74000 | BY7: =SUMIF('Agosto 24'!$E$5:$E$23,$A7,'Agosto 24'!$C$5:CQ$25) -> 74000 | BZ7: =SUMIF('Septiembre 24'!$E$5:$E$23,$A7,'Septiembre 24'!$C$5:CQ$25) -> 74000 | CA7: =SUMIF('Octubre 24'!$E$5:$E$23,$A7,'Octubre 24'!$C$5:CQ$25) -> 74000 | CB7: =SUMIF('Noviembre 24'!$E$5:$E$23,$A7,'Noviembre 24'!$C$5:CQ$25) -> 74000 | CC7: =SUMIF('Diciembre 24'!$E$5:$E$23,$A7,'Diciembre 24'!$C$5:CQ$25) -> 74000 | CD7: =SUMIF('Enero 25'!$E$5:$E$23,$A7,'Enero 25'!$C$5:CQ$25) -> 74000 | CE7: =SUMIF('febrero 25'!$E$5:$E$23,$A7,'febrero 25'!$C$5:CQ$25) -> 74000 | CF7: =SUMIF('marzo 25'!$E$5:$E$23,$A7,'marzo 25'!$C$5:CQ$25) -> 74000 | CG7: =SUMIF('abril 25'!$E$5:$E$23,$A7,'abril 25'!$C$5:CQ$25) -> 74000 | CH7: =SUMIF('Mayo 25'!$E$5:$E$23,$A7,'Mayo 25'!$C$5:CQ$25) -> 74000 | CI7: =SUMIF('Junio 25'!$E$5:$E$23,$A7,'Junio 25'!$C$5:CQ$25) -> 74000 | CJ7: =SUMIF('Julio 25'!$E$5:$E$23,$A7,'Julio 25'!$C$5:CQ$25) -> 74000 | CK7: =SUMIF('Agosto 25'!$E$5:$E$23,$A7,'Agosto 25'!$C$5:CQ$25) -> 111000 | CL7: =SUMIF('Septiembre 25'!$E$5:$E$23,$A7,'Septiembre 25'!$C$5:CQ$25) -> 111000 | CM7: =SUMIF('Octubre 25'!$E$5:$E$23,$A7,'Octubre 25'!$C$5:CQ$25) -> 111000 | CN7: =SUMIF('noviembre 25'!$E$5:$E$23,$A7,'noviembre 25'!$C$5:CQ$25) -> 111000
A8: Entel | B8: =MAX(BN8:ZZ8) -> 29850 | C8: =MIN(AK8:ZZ8) -> 17000 | D8: =AVERAGE(AK8:ZZ8) -> 22400.161 | E8: 37247 | F8: 39990 | G8: 39990 | H8: 39900 | I8: 39990 | J8: 39990 | K8: 45578 | L8: 45574 | M8: 45574 | N8: 11640 | O8: 25990 | P8: 25990 | Q8: 25990 | R8: 25990 | S8: 25990 | T8: =SUMIF('Noviembre 19'!$E$5:$E$23,$A8,'Noviembre 19'!$C$5:CQ$25) -> 21990 | U8: 21990 | V8: =SUMIF('Enero 20'!$E$5:$E$23,$A8,'Enero 20'!$C$5:CQ$25) -> 21990 | W8: =SUMIF('Febrero 20'!$E$5:$E$23,$A8,'Febrero 20'!$C$5:CQ$25) -> 21990 | X8: =SUMIF('Marzo 20'!$E$5:$E$23,$A8,'Marzo 20'!$C$5:CQ$25) -> 21990 | Y8: =SUMIF('Abril 20'!$E$5:$E$23,$A8,'Abril 20'!$C$5:CQ$25) -> 21990 | Z8: =SUMIF('Mayo 20'!$E$5:$E$23,$A8,'Mayo 20'!$C$5:CQ$25) -> 22124 | AA8: =SUMIF('Junio 20'!$E$5:$E$23,$A8,'Junio 20'!$C$5:CQ$25) -> 22124 | AB8: =SUMIF('Julio 20'!$E$5:$E$23,$A8,'Julio 20'!$C$5:CQ$25) -> 25990 | AC8: =SUMIF('Agosto 20'!$E$5:$E$23,$A8,'Agosto 20'!$C$5:CQ$25) -> 25990 | AD8: =SUMIF('Septiembre 20'!$E$5:$E$23,$A8,'Septiembre 20'!$C$5:CQ$25) -> 25990 | AE8: =SUMIF('octubre 20'!$E$5:$E$23,$A8,'octubre 20'!$C$5:CQ$25) -> 25990 | AF8: =SUMIF('noviembre 20'!$E$5:$E$23,$A8,'noviembre 20'!$C$5:CQ$25) -> 25990 | AG8: =SUMIF('diciembre 20'!$E$5:$E$23,$A8,'diciembre 20'!$C$5:CQ$25) -> 25990 | AH8: =SUMIF('enero 21'!$E$5:$E$23,$A8,'enero 21'!$C$5:CQ$25) -> 25990 | AI8: =SUMIF('febrero 21'!$E$5:$E$23,$A8,'febrero 21'!$C$5:CQ$25) -> 25990 | AJ8: =SUMIF('marzo 21'!$E$5:$E$23,$A8,'marzo 21'!$C$5:CQ$25) -> 25990 | AK8: =SUMIF('abril 21'!$E$5:$E$23,$A8,'abril 21'!$C$5:CQ$25) -> 21990 | AL8: =SUMIF('mayo 21'!$E$5:$E$23,$A8,'mayo 21'!$C$5:CQ$25) -> 21990 | AM8: =SUMIF('Junio 21'!$E$5:$E$23,$A8,'Junio 21'!$C$5:CQ$25) -> 21990 | AN8: =SUMIF('Julio 21'!$E$5:$E$23,$A8,'Julio 21'!$C$5:CQ$25) -> 21990 | AO8: =SUMIF('Agosto 21'!$E$5:$E$23,$A8,'Agosto 21'!$C$5:CQ$25) -> 21990 | AP8: =SUMIF('Septiembre 21'!$E$5:$E$23,$A8,'Septiembre 21'!$C$5:CQ$25) -> 21990 | AQ8: =SUMIF('Octubre 21'!$E$5:$E$23,$A8,'Octubre 21'!$C$5:CQ$25) -> 27990 | AR8: =SUMIF('Noviembre 21'!$E$5:$E$23,$A8,'Noviembre 21'!$C$5:CQ$25) -> 27990 | AS8: =SUMIF('Diciembre 21'!$E$5:$E$23,$A8,'Noviembre 21'!$C$5:CQ$25) -> 27990 | AT8: =SUMIF('Enero 22'!$E$5:$E$23,$A8,'Enero 22'!$C$5:CQ$25) -> 29190 | AU8: =SUMIF('Febrero 22'!$E$5:$E$23,$A8,'Febrero 22'!$C$5:CQ$25) -> 28420 | AV8: =SUMIF('Marzo 22'!$E$5:$E$23,$A8,'Marzo 22'!$C$5:CQ$25) -> 27990 | AW8: =SUMIF('Abril 22'!$E$5:$E$23,$A8,'Abril 22'!$C$5:CQ$25) -> 27990 | AX8: =SUMIF('Mayo 22'!$E$5:$E$23,$A8,'Mayo 22'!$C$5:CQ$25) -> 27990 | AY8: =SUMIF('Junio 22'!$E$5:$E$23,$A8,'Junio 22'!$C$5:CQ$25) -> 27990 | AZ8: =SUMIF('Julio 22'!$E$5:$E$23,$A8,'Julio 22'!$C$5:CQ$25) -> 27990 | BA8: =SUMIF('Agosto 22'!$E$5:$E$23,$A8,'Agosto 22'!$C$5:CQ$25) -> 27990 | BB8: =SUMIF('septiembre 22'!$E$5:$E$23,$A8,'septiembre 22'!$C$5:CQ$25) -> 27990 | BC8: =SUMIF('octubre 22'!$E$5:$E$23,$A8,'octubre 22'!$C$5:CQ$25) -> 27990 | BD8: =SUMIF('noviembre 22'!$E$5:$E$23,$A8,'noviembre 22'!$C$5:CQ$25) -> 27990 | BE8: =SUMIF('diciembre 22'!$E$5:$E$23,$A8,'noviembre 22'!$C$5:CQ$25) -> 27990 | BF8: =SUMIF('Enero 23'!$E$5:$E$23,$A8,'Enero 23'!$C$5:CQ$25) -> 27990 | BG8: =SUMIF('Febrero 23'!$E$5:$E$23,$A8,'Febrero 23'!$C$5:CQ$25) -> 27990 | BH8: =SUMIF('Marzo 23'!$E$5:$E$23,$A8,'Marzo 23'!$C$5:CQ$25) -> 27990 | BI8: =SUMIF('Abril 23'!$E$5:$E$23,$A8,'Abril 23'!$C$5:CQ$25) -> 19990 | BJ8: =SUMIF('Mayo 23'!$E$5:$E$23,$A8,'Mayo 23'!$C$5:CQ$25) -> 19990 | BK8: =SUMIF('Junio 23'!$E$5:$E$23,$A8,'Junio 23'!$C$5:CQ$25) -> 19990 | BL8: =SUMIF('Julio 23'!$E$5:$E$23,$A8,'Julio 23'!$C$5:CQ$25) -> 19990 | BM8: =SUMIF('Agosto 23'!$E$5:$E$23,$A8,'Agosto 23'!$C$5:CQ$25) -> 19990 | BN8: =SUMIF('Septiembre 23'!$E$5:$E$23,$A8,'Septiembre 23'!$C$5:CQ$25) -> 20718 | BO8: =SUMIF('Octubre 23'!$E$5:$E$23,$A8,'Octubre 23'!$C$5:CQ$25) -> 20718 | BP8: =SUMIF('Noviembre 23'!$E$5:$E$23,$A8,'Noviembre 23'!$C$5:CQ$25) -> 20718 | BQ8: =SUMIF('Diciembre 23'!$E$5:$E$23,$A8,'Diciembre 23'!$C$5:CQ$25) -> 20718 | BR8: =SUMIF('Enero 24'!$E$5:$E$23,$A8,'Enero 24'!$C$5:CQ$25) -> 21380 | BS8: =SUMIF('Febrero 24'!$E$5:$E$23,$A8,'Febrero 24'!$C$5:CQ$25) -> 21380 | BT8: =SUMIF('Marzo 24'!$E$5:$E$23,$A8,'Marzo 24'!$C$5:CQ$25) -> 21380 | BU8: =SUMIF('abril 24'!$E$5:$E$23,$A8,'abril 24'!$C$5:CQ$25) -> 29850 | BV8: =SUMIF('Mayo 24'!$E$5:$E$23,$A8,'Mayo 24'!$C$5:CQ$25) -> 19777 | BW8: =SUMIF('Junio 24'!$E$5:$E$23,$A8,'Junio 24'!$C$5:CQ$25) -> 17990 | BX8: =SUMIF('Julio 24'!$E$5:$E$23,$A8,'Julio 24'!$C$5:CQ$25) -> 17990 | BY8: =SUMIF('Agosto 24'!$E$5:$E$23,$A8,'Agosto 24'!$C$5:CQ$25) -> 17990 | BZ8: =SUMIF('Septiembre 24'!$E$5:$E$23,$A8,'Septiembre 24'!$C$5:CQ$25) -> 17990 | CA8: =SUMIF('Octubre 24'!$E$5:$E$23,$A8,'Octubre 24'!$C$5:CQ$25) -> 17990 | CB8: =SUMIF('Noviembre 24'!$E$5:$E$23,$A8,'Noviembre 24'!$C$5:CQ$25) -> 17990 | CC8: =SUMIF('Diciembre 24'!$E$5:$E$23,$A8,'Diciembre 24'!$C$5:CQ$25) -> 23990 | CD8: =SUMIF('Enero 25'!$E$5:$E$23,$A8,'Enero 25'!$C$5:CQ$25) -> 17000 | CE8: =SUMIF('febrero 25'!$E$5:$E$23,$A8,'febrero 25'!$C$5:CQ$25) -> 17000 | CF8: =SUMIF('marzo 25'!$E$5:$E$23,$A8,'marzo 25'!$C$5:CQ$25) -> 17000 | CG8: =SUMIF('abril 25'!$E$5:$E$23,$A8,'abril 25'!$C$5:CQ$25) -> 17000 | CH8: =SUMIF('Mayo 25'!$E$5:$E$23,$A8,'Mayo 25'!$C$5:CQ$25) -> 17000 | CI8: =SUMIF('Junio 25'!$E$5:$E$23,$A8,'Junio 25'!$C$5:CQ$25) -> 17000 | CJ8: =SUMIF('Julio 25'!$E$5:$E$23,$A8,'Julio 25'!$C$5:CQ$25) -> 17000 | CK8: =SUMIF('Agosto 25'!$E$5:$E$23,$A8,'Agosto 25'!$C$5:CQ$25) -> 17000 | CL8: =SUMIF('Septiembre 25'!$E$5:$E$23,$A8,'Septiembre 25'!$C$5:CQ$25) -> 17500 | CM8: =SUMIF('Octubre 25'!$E$5:$E$23,$A8,'Octubre 25'!$C$5:CQ$25) -> 17500 | CN8: =SUMIF('noviembre 25'!$E$5:$E$23,$A8,'noviembre 25'!$C$5:CQ$25) -> 17500
A9: Luz | B9: =MAX(BN9:ZZ9) -> 82107 | C9: =MIN(AK9:ZZ9) -> 0 | D9: =AVERAGE(AK9:ZZ9) -> 22993.179 | E9: =SUMIF(Agosto!$E$5:$E$25,$A9,Agosto!$C$5:$C$25) -> 1656 | F9: =SUMIF(Septiembre!$E$5:$E$25,$A9,Septiembre!$C$5:$C$25) -> 1547 | G9: =SUMIF(octubre!$E$5:E$25,$A9,octubre!$C$5:$C$25) -> 3627 | H9: =SUMIF(noviembre!$E$5:F$25,$A9,noviembre!$C$5:$C$25) -> 2979 | I9: =SUMIF(Diciembre!$E$5:CQ$25,$A9,Diciembre!$C$5:$C$25) -> 2927 | J9: =SUMIF(Enero!$E$5:E$25,$A9,Enero!$C$5:$C$25) -> 3949 | K9: =SUMIF(febrero!$E$5:$E$25,$A9,febrero!$C$5:CQ$25) -> 9704 | L9: =SUMIF(Marzo!$E$5:$E$25,$A9,Marzo!$C$5:CQ$25) -> 9186 | M9: =SUMIF(Abril!$E$5:$E$25,$A9,Abril!$C$5:CQ$25) -> 8331 | N9: =SUMIF(Mayo!$E$5:$E$25,$A9,Mayo!$C$5:CQ$25) -> 11678 | O9: =SUMIF(Junio!$E$5:$E$25,$A9,Junio!$C$5:CQ$25) -> 9116 | P9: =SUMIF(Julio!$E$5:$E$25,$A9,Julio!$C$5:CQ$25) -> 7713 | Q9: =SUMIF('Agosto 19'!$E$5:$E$23,$A9,'Agosto 19'!$C$5:CQ$25) -> 9869 | R9: =SUMIF('Septiembre 19'!$E$5:$E$23,$A9,'Septiembre 19'!$C$5:CQ$25) -> 10800 | S9: =SUMIF('Octubre 19'!$E$5:$E$23,$A9,'Octubre 19'!$C$5:CQ$25) -> 8434 | T9: =SUMIF('Noviembre 19'!$E$5:$E$23,$A9,'Noviembre 19'!$C$5:CQ$25) -> 8668 | U9: =SUMIF('Diciembre 19'!$E$5:$E$23,$A9,'Diciembre 19'!$C$5:CQ$25) -> 7089 | V9: =SUMIF('Enero 20'!$E$5:$E$23,$A9,'Enero 20'!$C$5:CQ$25) -> 11963 | W9: =SUMIF('Febrero 20'!$E$5:$E$23,$A9,'Febrero 20'!$C$5:CQ$25) -> 18702 | X9: =SUMIF('Marzo 20'!$E$5:$E$23,$A9,'Marzo 20'!$C$5:CQ$25) -> 18004 | Y9: =SUMIF('Abril 20'!$E$5:$E$23,$A9,'Abril 20'!$C$5:CQ$25) -> 12150 | Z9: =SUMIF('Mayo 20'!$E$5:$E$23,$A9,'Mayo 20'!$C$5:CQ$25) -> 14606 | AA9: =SUMIF('Junio 20'!$E$5:$E$23,$A9,'Junio 20'!$C$5:CQ$25) -> 14385 | AB9: =SUMIF('Julio 20'!$E$5:$E$23,$A9,'Julio 20'!$C$5:CQ$25) -> 15128 | AC9: =SUMIF('Agosto 20'!$E$5:$E$23,$A9,'Agosto 20'!$C$5:CQ$25) -> 16119 | AD9: =SUMIF('Septiembre 20'!$E$5:$E$23,$A9,'Septiembre 20'!$C$5:CQ$25) -> 12028 | AE9: =SUMIF('octubre 20'!$E$5:$E$23,$A9,'octubre 20'!$C$5:CQ$25) -> 0 | AF9: =SUMIF('noviembre 20'!$E$5:$E$23,$A9,'noviembre 20'!$C$5:CQ$25) -> 11500 | AG9: =SUMIF('diciembre 20'!$E$5:$E$23,$A9,'diciembre 20'!$C$5:CQ$25) -> 11466 | AH9: =SUMIF('enero 21'!$E$5:$E$23,$A9,'enero 21'!$C$5:CQ$25) -> 16191 | AI9: =SUMIF('febrero 21'!$E$5:$E$23,$A9,'febrero 21'!$C$5:CQ$25) -> 9873 | AJ9: =SUMIF('marzo 21'!$E$5:$E$23,$A9,'marzo 21'!$C$5:CQ$25) -> 9216 | AK9: =SUMIF('abril 21'!$E$5:$E$23,$A9,'abril 21'!$C$5:CQ$25) -> 16185 | AL9: =SUMIF('mayo 21'!$E$5:$E$23,$A9,'mayo 21'!$C$5:CQ$25) -> 26468 | AM9: =SUMIF('Junio 21'!$E$5:$E$23,$A9,'Junio 21'!$C$5:CQ$25) -> 14181 | AN9: =SUMIF('Julio 21'!$E$5:$E$23,$A9,'Julio 21'!$C$5:CQ$25) -> 7818 | AO9: =SUMIF('Agosto 21'!$E$5:$E$23,$A9,'Agosto 21'!$C$5:CQ$25) -> 12000 | AP9: =SUMIF('Septiembre 21'!$E$5:$E$23,$A9,'Septiembre 21'!$C$5:CQ$25) -> 0 | AQ9: =SUMIF('Octubre 21'!$E$5:$E$23,$A9,'Octubre 21'!$C$5:CQ$25) -> 13200 | AR9: =SUMIF('Noviembre 21'!$E$5:$E$23,$A9,'Noviembre 21'!$C$5:CQ$25) -> 13852 | AS9: =SUMIF('Diciembre 21'!$E$5:$E$23,$A9,'Noviembre 21'!$C$5:CQ$25) -> 13852 | AT9: =SUMIF('Enero 22'!$E$5:$E$23,$A9,'Enero 22'!$C$5:CQ$25) -> 12600 | AU9: =SUMIF('Febrero 22'!$E$5:$E$23,$A9,'Febrero 22'!$C$5:CQ$25) -> 10841 | AV9: =SUMIF('Marzo 22'!$E$5:$E$23,$A9,'Marzo 22'!$C$5:CQ$25) -> 8900 | AW9: =SUMIF('Abril 22'!$E$5:$E$23,$A9,'Abril 22'!$C$5:CQ$25) -> 9255 | AX9: =SUMIF('Mayo 22'!$E$5:$E$23,$A9,'Mayo 22'!$C$5:CQ$25) -> 10563 | AY9: =SUMIF('Junio 22'!$E$5:$E$23,$A9,'Junio 22'!$C$5:CQ$25) -> 12000 | AZ9: =SUMIF('Julio 22'!$E$5:$E$23,$A9,'Julio 22'!$C$5:CQ$25) -> 19300 | BA9: =SUMIF('Agosto 22'!$E$5:$E$23,$A9,'Agosto 22'!$C$5:CQ$25) -> 19971 | BB9: =SUMIF('septiembre 22'!$E$5:$E$23,$A9,'septiembre 22'!$C$5:CQ$25) -> 11058 | BC9: =SUMIF('octubre 22'!$E$5:$E$23,$A9,'octubre 22'!$C$5:CQ$25) -> 0 | BD9: =SUMIF('noviembre 22'!$E$5:$E$23,$A9,'noviembre 22'!$C$5:CQ$25) -> 9672 | BE9: =SUMIF('diciembre 22'!$E$5:$E$23,$A9,'noviembre 22'!$C$5:CQ$25) -> 9672 | BF9: =SUMIF('Enero 23'!$E$5:$E$23,$A9,'Enero 23'!$C$5:CQ$25) -> 11091 | BG9: =SUMIF('Febrero 23'!$E$5:$E$23,$A9,'Febrero 23'!$C$5:CQ$25) -> 9867 | BH9: =SUMIF('Marzo 23'!$E$5:$E$23,$A9,'Marzo 23'!$C$5:CQ$25) -> 9602 | BI9: =SUMIF('Abril 23'!$E$5:$E$23,$A9,'Abril 23'!$C$5:CQ$25) -> 8000 | BJ9: =SUMIF('Mayo 23'!$E$5:$E$23,$A9,'Mayo 23'!$C$5:CQ$25) -> 8324 | BK9: =SUMIF('Junio 23'!$E$5:$E$23,$A9,'Junio 23'!$C$5:CQ$25) -> 7308 | BL9: =SUMIF('Julio 23'!$E$5:$E$23,$A9,'Julio 23'!$C$5:CQ$25) -> 15117 | BM9: =SUMIF('Agosto 23'!$E$5:$E$23,$A9,'Agosto 23'!$C$5:CQ$25) -> 13890 | BN9: =SUMIF('Septiembre 23'!$E$5:$E$23,$A9,'Septiembre 23'!$C$5:CQ$25) -> 21446 | BO9: =SUMIF('Octubre 23'!$E$5:$E$23,$A9,'Octubre 23'!$C$5:CQ$25) -> 15300 | BP9: =SUMIF('Noviembre 23'!$E$5:$E$23,$A9,'Noviembre 23'!$C$5:CQ$25) -> 15695 | BQ9: =SUMIF('Diciembre 23'!$E$5:$E$23,$A9,'Diciembre 23'!$C$5:CQ$25) -> 16507 | BR9: =SUMIF('Enero 24'!$E$5:$E$23,$A9,'Enero 24'!$C$5:CQ$25) -> 30073 | BS9: =SUMIF('Febrero 24'!$E$5:$E$23,$A9,'Febrero 24'!$C$5:CQ$25) -> 36500 | BT9: =SUMIF('Marzo 24'!$E$5:$E$23,$A9,'Marzo 24'!$C$5:CQ$25) -> 41316 | BU9: =SUMIF('abril 24'!$E$5:$E$23,$A9,'abril 24'!$C$5:CQ$25) -> 26500 | BV9: =SUMIF('Mayo 24'!$E$5:$E$23,$A9,'Mayo 24'!$C$5:CQ$25) -> 30617 | BW9: =SUMIF('Junio 24'!$E$5:$E$23,$A9,'Junio 24'!$C$5:CQ$25) -> 35993 | BX9: =SUMIF('Julio 24'!$E$5:$E$23,$A9,'Julio 24'!$C$5:CQ$25) -> 38894 | BY9: =SUMIF('Agosto 24'!$E$5:$E$23,$A9,'Agosto 24'!$C$5:CQ$25) -> 38432 | BZ9: =SUMIF('Septiembre 24'!$E$5:$E$23,$A9,'Septiembre 24'!$C$5:CQ$25) -> 27697 | CA9: =SUMIF('Octubre 24'!$E$5:$E$23,$A9,'Octubre 24'!$C$5:CQ$25) -> 24676 | CB9: =SUMIF('Noviembre 24'!$E$5:$E$23,$A9,'Noviembre 24'!$C$5:CQ$25) -> 43800 | CC9: =SUMIF('Diciembre 24'!$E$5:$E$23,$A9,'Diciembre 24'!$C$5:CQ$25) -> 24064 | CD9: =SUMIF('Enero 25'!$E$5:$E$23,$A9,'Enero 25'!$C$5:CQ$25) -> 82107 | CE9: =SUMIF('febrero 25'!$E$5:$E$23,$A9,'febrero 25'!$C$5:CQ$25) -> 66739 | CF9: =SUMIF('marzo 25'!$E$5:$E$23,$A9,'marzo 25'!$C$5:CQ$25) -> 40200 | CG9: =SUMIF('abril 25'!$E$5:$E$23,$A9,'abril 25'!$C$5:CQ$25) -> 32500 | CH9: =SUMIF('Mayo 25'!$E$5:$E$23,$A9,'Mayo 25'!$C$5:CQ$25) -> 31500 | CI9: =SUMIF('Junio 25'!$E$5:$E$23,$A9,'Junio 25'!$C$5:CQ$25) -> 36000 | CJ9: =SUMIF('Julio 25'!$E$5:$E$23,$A9,'Julio 25'!$C$5:CQ$25) -> 49275 | CK9: =SUMIF('Agosto 25'!$E$5:$E$23,$A9,'Agosto 25'!$C$5:CQ$25) -> 57000 | CL9: =SUMIF('Septiembre 25'!$E$5:$E$23,$A9,'Septiembre 25'!$C$5:CQ$25) -> 41200 | CM9: =SUMIF('Octubre 25'!$E$5:$E$23,$A9,'Octubre 25'!$C$5:CQ$25) -> 29000 | CN9: =SUMIF('noviembre 25'!$E$5:$E$23,$A9,'noviembre 25'!$C$5:CQ$25) -> 20000
